Workbook

Sheet 01 Preliminaries
A1: Item Code | B1: Item Name | C1: Item Details | D1: Additional Information | E1: UOM | F1: Quantity | G1: Unit Price | H1: Total Price In Figure
A2: P1 | B2: Preliminary and General Requirements Tender Drawings | C2: Notes | D2: All items will be priced individually. Any item not priced hereunder will be deemed to be included in the Contractors Tender. | E2: Item | F2: 0 | G2: 0 | H2: =F2*G2 -> 0
A3: P2 | B3: Preliminary and General Requirements Tender Drawings | C3: Tender Drawings | D3: The Tender Drawings are listed in Volume 4 Tender Drawings. | E3: Item | F3: 1 | G3: 0 | H3: =F3*G3 -> 0
A4: P3 | B4: Preliminary and General Requirements Conditions of Contract | C4: Conditions of Contract | D4: The Conditions of Contract shall be those contained within the Sultanate of Oman Standard Documents for Building and Civil Engineering Works prepared and issued by the Ministry of Finance Muscat. | E4: Item | F4: 1 | G4: 0 | H4: =F4*G4 -> 0
A5: P4 | B5: Preliminary and General Requirements Conditions of Contract | C5: Conditions of Contract | D5: The Contractor shall allow for complying in all respect with the Conditions of Contract. | E5: Item | F5: 1 | G5: 0 | H5: =F5*G5 -> 0
A6: P5 | B6: Preliminary and General Requirements Contractors Administration Arrangements | C6: Drawings | D6: The Contractor shall be responsible for checking all drawings and schedule etc. supplied by the Engineer. In the event of any discrepancy being found between such drawings and schedules etc. or if the Contractor considers that additional detail drawings are required then in either case the Contractor shall report such discrepancy to the Engineer for instruction or apply in writing for such detail drawings at least 28 days before the materials and components necessary for the works are to be placed on order by the Contractor. | E6: Item | F6: 1 | G6: 0 | H6: =F6*G6 -> 0
A7: P6 | B7: Preliminary and General Requirements Contractors Administration Arrangements | C7: Drawings | D7: The Contractor shall ascertain from the drawings or otherwise any holes recesses plugs etc. which may be required in time to form these as the work proceeds. No extra payments will be allowed for cuttings or forming such holes subsequently. | E7: Item | F7: 1 | G7: 0 | H7: =F7*G7 -> 0
A8: P7 | B8: Preliminary and General Requirements Contractors Administration Arrangements | C8: Drawings | D8: The Contractor will prepare at his own cost detailed working and shop drawings that may require supplementary to the construction drawings furnished by the Engineer. | E8: Item | F8: 1 | G8: 0 | H8: =F8*G8 -> 0
A9: P8 | B9: Preliminary and General Requirements Contractors Administration Arrangements | C9: Drawings | D9: The detail and working drawing for civil and building works shall be prepared by the contractor supplement the construction drawings furnished by the Engineer will include Reinforcement details and Other drawings. | E9: Item | F9: 1 | G9: 10500 | H9: =F9*G9 -> 10500
A10: P9 | B10: Preliminary and General Requirements Contractors Administration Arrangements | C10: Drawings | D10: The detail and working drawing for civil and building works shall be prepared by the contractor supplement the construction drawings furnished by the Engineer will include the Drawings and details of foundation for equipment machinery and technical installation. | E10: Item | F10: 1 | G10: 10500 | H10: =F10*G10 -> 10500
A11: P10 | B11: Preliminary and General Requirements Contractors Administration Arrangements | C11: Drawings | D11: Such drawing and detail will depend on the type and make of the equipment offered and will include in particular foundations etc. for the standby power generators chiller and radiators transformers ventilation and airconditioning equipment etc. Construction details as required. | E11: Item | F11: 1 | G11: 0 | H11: =F11*G11 -> 0
A12: P11 | B12: Preliminary and General Requirements Contractors Administration Arrangements | C12: Drawings | D12: No drawing etc. prepared by the Contractor shall be used in the works before the Engineer has approved it. | E12: Item | F12: 1 | G12: 0 | H12: =F12*G12 -> 0
A13: P12 | B13: Preliminary and General Requirements Contractors Administration Arrangements | C13: Drawings | D13: The Contractor shall submit to the Engineer for his approval two copies of all his detail working or shop drawings and related documents produced by him for use in construction work. Any changes or modifications considered necessary by the Engineer shall be made at no extra cost to the Employer. | E13: Item | F13: 1 | G13: 0 | H13: =F13*G13 -> 0
... A50: P49 | B50: Preliminary and General Requirements Contractors Administration Arrangements | C50: Site Transportation | D50: Provide all necessary vehicles and other site transport etc. with all consumables store etc. as described for small plant and tools etc. | E50: Item | F50: 1 | G50: 0 | H50: =F50*G50 -> 0
A51: P50 | B51: Preliminary and General Requirements Employer Facilities | C51: Temporary Office | D51: Provide erect furnish equip maintain and remove three month after completion of the Contract fully serviced furnished and equipped airconditioned offices and a conference room for the exclusive use of the Engineer all as described in General Requirement of the Architectural Specification. | E51: Item | F51: 1 | G51: 0 | H51: =F51*G51 -> 0 | I51: =SUM(H2:H51) -> 24150
A52: P51 | B52: Preliminary and General Requirements Employer Facilities | C52: Temporary Office | D52: The offices shall be provided and maintained throughout the period of the Contract. | E52: Item | F52: 1 | G52: 0 | H52: =F52*G52 -> 0
A53: P52 | B53: Preliminary and General Requirements Employer Facilities | C53: Temporary Office | D53: The Contractor shall be responsible for providing security power water drainage safety helmets safety boots daily cleaning car parking and other facilities to the Engineers offices. | E53: Item | F53: 1 | G53: 0 | H53: =F53*G53 -> 0
A54: P53 | B54: Preliminary and General Requirements Employer Facilities | C54: Temporary Office | D54: The Contractor shall be responsible during the continuance of the Contract for satisfactorily maintain and security of the offices and for all plans documents and paper and other articles contained there in. | E54: Item | F54: 1 | G54: 0 | H54: =F54*G54 -> 0
A55: P54 | B55: Preliminary and General Requirements Employer Facilities | C55: Telephone for the Engineer and Employer | D55: Allow for providing the Engineers site office with an independent telephone service until removal of office and for paying all charges incurred by the Engineers staff for business calls concerning the project within the Sultanate of Oman. | E55: Item | F55: 1 | G55: 1050 | H55: =F55*G55 -> 1050
A56: P55 | B56: Preliminary and General Requirements Employer Facilities | C56: Attendance on the Engineer | D56: Provide attendance and assistance to the Engineer all as described in the Specification. | E56: Item | F56: 1 | G56: 0 | H56: =F56*G56 -> 0
A57: P56 | B57: Preliminary and General Requirements Employer Facilities | C57: Surveying and other equipment | D57: The Contractor shall provide to the Engineer for his exclusive use all survey equipment and electrical test equipment as described in the Specification. | E57: Item | F57: 1 | G57: 1575 | H57: =F57*G57 -> 1575
A58: P57 | B58: Preliminary and General Requirements Employer Facilities | C58: Mobilisation | D58: The Engineer may issue the notice to proceed at any time within the period of validity of the tender. After the date of the notice to proceed the Contractor shall have a period of 120 days to complete mobilisation and to be completely prepared for the work. After the mobilisation is complete the work shall be carried out in accordance with the requirements of this Contract. | E58: Item | F58: 1 | G58: 0 | H58: =F58*G58 -> 0
A59: P58 | B59: Preliminary and General Requirements Employer Facilities | C59: Programme and Order of Works | D59: Within 14 days of receipt of an order to commence the Works the Contractor shall submit to the Engineer a detailed programme in respect of all works contained in the scope of works including temporary works and services. | E59: Item | F59: 1 | G59: 0 | H59: =F59*G59 -> 0
A60: P59 | B60: Preliminary and General Requirements Employer Facilities | C60: Programme and Order of Works | D60: Within 21 days of receipt of an order to commence the Works the Contractor shall submit to the Engineer a detailed programme in respect of all trades separately for each building section and external works and services together with the target dates for receipt of information required to enable the Contractor to comply with this programme. | E60: Item | F60: 1 | G60: 0 | H60: =F60*G60 -> 0
A61: P60 | B61: Preliminary and General Requirements Employer Facilities | C61: Programme and Order of Works | D61: In addition the Contractor shall at the same time submit to the Engineer a detailed schedule of items and information that he requires instruction upon for early ordering schedules. | E61: Item | F61: 1 | G61: 0 | H61: =F61*G61 -> 0
A62: P61 | B62: Preliminary and General Requirements Employer Facilities | C62: Coordination | D62: The Contractors attention is drawn to the fact that he shall be entirely responsible for the coordination of all works carried out by both his own workmen and the workmen of SubContractors and shall be responsible for ensuring that all SubContractors shop andor working drawings are submitted to the Engineer for approval in such time as not to prejudice the expeditious execution of the Works in accordance with the Contractors programme. | E62: Item | F62: 1 | G62: 0 | H62: =F62*G62 -> 0
A63: P62 | B63: Preliminary and General Requirements Employer Facilities | C63: Reports | D63: Provide and maintain daily reports and delivery records for inspection by the Engineer. Such reports must give details of number and category of labour force list of plant list of material deliveries work planned and work carried out climatic conditions high and low temperature and any other information required by the Engineer. | E63: Item | F63: 1 | G63: 0 | H63: =F63*G63 -> 0
... A100: P99 | B100: Preliminary and General Requirements | C100: Sundry ItemsSite Survey and Grid of Levels | D100: Before commencing excavation or site levelling operations the Contractor shall conduct a coordinated site survey witnessed by the Engineer related to a bench mark referred to in the Contract document and shall prepare a site plan showing a grid of levels at 5 m centres to the proposed site the Contractor shall provide the Engineer with one transparency and two copies of the site survey plan. | E100: Item | F100: 1 | G100: 0 | H100: =F100*G100 -> 0
A101: P100 | B101: Preliminary and General Requirements | C101: Sundry ItemsSite Survey and Grid of Levels | D101: The Contractor shall conduct similar site survey after site levelling operations and external works have been completed and provide drawings as above. | E101: Item | F101: 1 | G101: 0 | H101: =F101*G101 -> 0 | I101: =SUM(H52:H101) -> 44730
A102: P101 | B102: Preliminary and General Requirements | C102: Sundry ItemsCopies of Orders | D102: Provide the Engineers Representative with a copy of all orders for the supply of such materials or goods required in connection with the Works as the Engineers Representative may specify. | E102: Item | F102: 1 | G102: 0 | H102: =F102*G102 -> 0
A103: P102 | B103: Preliminary and General Requirements | C103: Sundry ItemsWorking Drawings | D103: Allow for preparing and submission to the Engineer of all working drawings and operation and maintenance instructions as detailed in the specification if these costs are not specifically measured elsewhere in the relevant sections of this document. | E103: Item | F103: 1 | G103: 0 | H103: =F103*G103 -> 0
A104: P103 | B104: Preliminary and General Requirements | C104: Sundry ItemsWorking Drawings | D104: Upon completion of the works submit two sets of diskettes Autocad R12 later two transparencies and four copies of all drawings duly marked AsBuilt clearly defining all locations depths shapes and dimensions of all permanent works executed. | E104: Item | F104: 1 | G104: 0 | H104: =F104*G104 -> 0
A105: P104 | B105: Preliminary and General Requirements | C105: Sundry ItemsTraining of Employers Personnel | D105: During the execution of the Works the Contractor shall provide such assistance as may be necessary for the instruction and training of personnel appointed by the Employer. | E105: Item | F105: 1 | G105: 0 | H105: =F105*G105 -> 0
A106: P105 | B106: Preliminary and General Requirements | C106: Sundry ItemsTraining of Employers Personnel | D106: The Contractor shall provide all necessary instruction material for this purpose such as manuals booklets pamphlets drawings sketches models pictures photoscolour slides films etc. This instruction material shall become the property of the Employer. | E106: Item | F106: 1 | G106: 0 | H106: =F106*G106 -> 0
A107: P106 | B107: Preliminary and General Requirements | C107: Sundry ItemsDirect Contractors | D107: The Tenderers attention is drawn to the fact that the Employer may appoint other Contractors to carry out certain items of Specialist Works in accordance with Clause 31 of the Conditions of Contract. | E107: Item | F107: 1 | G107: 0 | H107: =F107*G107 -> 0
A108: P107 | B108: Preliminary and General Requirements Performance Bond Advance Payment Bond and Insurance Certificate | C108: Performance Bond | D108: The Contractor will be required to provide Performance Bond all in accordance with Clause 4.2 of the Conditions of Contract. | E108: Item | F108: 1 | G108: 0 | H108: =F108*G108 -> 0
A109: P108 | B109: Preliminary and General Requirements Performance Bond Advance Payment Bond and Insurance Certificate | C109: Insurance | D109: The Contractor will be required to provide all Insurances in accordance with the Conditions of Contract. | E109: Item | F109: 1 | G109: 0 | H109: =F109*G109 -> 0
A110: P109 | B110: Preliminary and General Requirements Performance Bond Advance Payment Bond and Insurance Certificate | C110: Insurance Declaration | D110: On signing the Contract the Contractor shall obtain from his Insurance Company and lodge with the Engineer a declaration that the insurance provided is strictly in accordance with all relevant Clause in the Conditions of Contract. This shall also include insurance against damage of any kind to existing buildings which may arise as a result of the building operations. | E110: Item | F110: 1 | G110: 0 | H110: =F110*G110 -> 0
A111: P110 | B111: Preliminary and General Requirements Performance Bond Advance Payment Bond and Insurance Certificate | C111: Advance Payment Bond | D111: The Contractor will be required to provide an Advance Payment Bond all in accordance with Clause 14.2 of Conditions of Contract. | E111: Item | F111: 1 | G111: 0 | H111: =F111*G111 -> 0
A112: P111 | B112: Preliminary and General Requirements Temporary Facilities. | C112: Refer Provisional SumTemporary Houses | D112: The Contractor will be required to provide temporary houses Caravan for the resident while working in the Construction and also during Maintenance Works and refix inside houses after work finish as outside extra rooms for them. Every caravan will be around 65m2 and will include and not be limited to 2 rooms a hall a kitchen and two toilets The structure to use steel structure painted with anticorrosion paint with isolated walls and roof aluminum sandwich panels 50 mm thickness from 2 sheets 0.7 mm thickness and foam of 45 kgm3 density internal ceramic floor and walls for toiles and kitchen to be ceramic all sanitary fixture for toilet and kitchen sink and cabinet sewage electrical and water connection to be done in the temporary place and will be finally done again after move to internal new and maintained houses foundation for caravan and 3 steps omani marble in final place fixing also 4 AC are included design of caravan to be done by the contractor approved by clientconsultant beforedelivery the caravans will be under project defects notification period for one year. | E112: item | F112: 1 | G112: 124800 | H112: =F112*G112 -> 124800
...

Sheet 02 Dayworks
A1: Item Code | B1: Item Name | C1: Item Details | D1: Additional Information | E1: UOM | F1: Quantity | G1: Unit Price | H1: Total Price In Figure
A2: D1 | B2: Daywork Schedule | C2: Day Work | D2: The Contractor may be required to execute certain works on the basis of day works. | E2: Item | F2: 1 | G2: 0 | H2: =F2*G2 -> 0
A3: D2 | B3: Daywork Schedule | C3: Day Work | D3: The Contractor shall keep an accurate record of time spent and materials and plant and used on each separate instruction given. Day work sheets are to be numbered and are to describe fully the instructions to which they refer and they are to be fully summarized fully priced and submitted to the Engineer for signature. The submission of such day work sheets does not necessarily mean that the work will be valued under Clause 13.5 of the Conditions of Contract or that any payment is in fact due. | E3: Item | F3: 1 | G3: 0 | H3: =F3*G3 -> 0
A4: D3 | B4: Daywork Schedule | C4: Labour 1. The Tenderer shall give the rates herein required for labourers and craftsmen against each item stated. 2.The rates are to be comprehensive and include | D4: Wages and all costs payments and charges including pensions annual and public holidays traveling time expenses fares and transport guaranteed time nonproductive time and other expenses in connection with overtime incentive and bonus payments dirty money and danger money and other disbursements arising from employment of labour including redundancy payment reduced working hours during Ramadhan all associated costs if labourers imported form other countries and workmens compensation insurance gratuity and all terminal benefits as per Oman labour Laws. | E4: Item | F4: 1 | G4: 0 | H4: =F4*G4 -> 0
A5: D4 | B5: Daywork Schedule | C5: Labour 1. The Tenderer shall give the rates herein required for labourers and craftsmen against each item stated. 2.The rates are to be comprehensive and include | D5: Charges incurred in respect of site and office supervision including foreman�s time and extra emoluments paid to foreman and leading craftsmen and gangers. | E5: Item | F5: 1 | G5: 0 | H5: =F5*G5 -> 0
A6: D5 | B6: Daywork Schedule | C6: Labour 1. The Tenderer shall give the rates herein required for labourers and craftsmen against each item stated. 2.The rates are to be comprehensive and include | D6: Site and Head Office overhead charges such as rent rates insurances electricity fuel water printing stationery postage telephone charges motor car expenses renewals maintenance and depreciation of premises machinery plant and the like. | E6: Item | F6: 1 | G6: 0 | H6: =F6*G6 -> 0
A7: D6 | B7: Daywork Schedule | C7: Labour 1. The Tenderer shall give the rates herein required for labourers and craftsmen against each item stated. 2.The rates are to be comprehensive and include | D7: Profit | E7: Item | F7: 1 | G7: 0 | H7: =F7*G7 -> 0
A8: D7 | B8: Daywork Schedule | C8: Materials | D8: Materials used in day works to be charged at invoice cost. All discounts are to be allowed to the Ministry of Health. Invoices are to be made available to the Engineer at the time the relevant day work sheets are submitted. | E8: Item | F8: 1 | G8: 0 | H8: =F8*G8 -> 0
A9: D8 | B9: Daywork Schedule | C9: Materials | D9: The Contractor is to allow for additional percentage he requires to be added to the invoice cost of materials to cover for ordering taking delivery paying all insurances in transit landing charges dues custom duties Municipality tax and all other charges loading and transporting to the site taking into store storing as may be required and all other charges and profit. | E9: Item | F9: 1 | G9: 0 | H9: =F9*G9 -> 0
A10: D9 | B10: Daywork Schedule | C10: Plant 1. The Contractor shall give here the rates he requires for plant and machinery 2. The rates are to be comprehensive and include | D10: Mobilization and demobilization costs | E10: Item | F10: 1 | G10: 0 | H10: =F10*G10 -> 0
A11: D10 | B11: Daywork Schedule | C11: Plant 1. The Contractor shall give here the rates he requires for plant and machinery 2. The rates are to be comprehensive and include | D11: Fuel oil lubricants and all other consumable stores. | E11: Item | F11: 1 | G11: 0 | H11: =F11*G11 -> 0
A12: D11 | B12: Daywork Schedule | C12: Plant 1. The Contractor shall give here the rates he requires for plant and machinery 2. The rates are to be comprehensive and include | D12: Servicing repairs and replacements. | E12: Item | F12: 1 | G12: 0 | H12: =F12*G12 -> 0
A13: D12 | B13: Daywork Schedule | C13: Plant 1. The Contractor shall give here the rates he requires for plant and machinery 2. The rates are to be comprehensive and include | D13: Site and Head Office overhead charges as previously defined. | E13: Item | F13: 1 | G13: 0 | H13: =F13*G13 -> 0
... A50: D49 | B50: Daywork Schedule | C50: Plant | D50: Roller 4 tonne | E50: Hr | F50: 25 | G50: 42 | H50: =F50*G50 -> 1050
A51: D50 | B51: Daywork Schedule | C51: Plant | D51: Welding set 300 A including electrodes | E51: Hr | F51: 25 | G51: 31.5 | H51: =F51*G51 -> 787.5 | I51: =SUM(H2:H51) -> 24675
A52: D51 | B52: Daywork Schedule | C52: Plant | D52: Oxy acetylene cutting set including electrodes | E52: Hr | F52: 25 | G52: 31.5 | H52: =F52*G52 -> 787.5
A53: D52 | B53: Daywork Schedule | C53: Plant | D53: 2 inch Water pump 5 hp | E53: Hr | F53: 30 | G53: 26.25 | H53: =F53*G53 -> 787.5
A54: D53 | B54: Daywork Schedule | C54: Plant | D54: 4 inch Water pump 10 hp | E54: Hr | F54: 30 | G54: 36.75 | H54: =F54*G54 -> 1102.5
A55: D54 | B55: Daywork Schedule | C55: Employee Staff | D55: Project Manager | E55: Hr | F55: 200 | G55: 42 | H55: =F55*G55 -> 8400
A56: D55 | B56: Daywork Schedule | C56: Employee Staff | D56: Resident Project Engineer | E56: Hr | F56: 200 | G56: 26.25 | H56: =F56*G56 -> 5250
A57: D56 | B57: Daywork Schedule | C57: Employee Staff | D57: Resident Civil Material Engineer | E57: Hr | F57: 200 | G57: 26.25 | H57: =F57*G57 -> 5250
A58: D57 | B58: Daywork Schedule | C58: Employee Staff | D58: Resident Electrical Engineer | E58: Hr | F58: 200 | G58: 26.25 | H58: =F58*G58 -> 5250
A59: D58 | B59: Daywork Schedule | C59: Employee Staff | D59: Resident Mechanical Engineer | E59: Hr | F59: 200 | G59: 26.25 | H59: =F59*G59 -> 5250
A60: D59 | B60: Daywork Schedule | C60: Employee Staff | D60: Resident Architecture Engineer Omani | E60: Hr | F60: 200 | G60: 26.25 | H60: =F60*G60 -> 5250
A61: D60 | B61: Daywork Schedule | C61: Employee Staff | D61: Resident Quantity Surveyor | E61: Hr | F61: 200 | G61: 26.25 | H61: =F61*G61 -> 5250
A62: D61 | B62: Daywork Schedule | C62: Employee Staff | D62: Resident Draftsman Omani | E62: Hr | F62: 200 | G62: 26.25 | H62: =F62*G62 -> 5250
A63: D62 | B63: Daywork Schedule | C63: Employee Staff | D63: Resident QA QC | E63: Hr | F63: 200 | G63: 26.25 | H63: =F63*G63 -> 5250
... A100: P99 | B100: Preliminary and General Requirements | C100: Sundry ItemsSite Survey and Grid of Levels | D100: Before commencing excavation or site levelling operations the Contractor shall conduct a coordinated site survey witnessed by the Engineer related to a bench mark referred to in the Contract document and shall prepare a site plan showing a grid of levels at 5 m centres to the proposed site the Contractor shall provide the Engineer with one transparency and two copies of the site survey plan. | E100: Item | F100: 1 | G100: 0 | H100: =F100*G100 -> 0
A101: P100 | B101: Preliminary and General Requirements | C101: Sundry ItemsSite Survey and Grid of Levels | D101: The Contractor shall conduct similar site survey after site levelling operations and external works have been completed and provide drawings as above. | E101: Item | F101: 1 | G101: 0 | H101: =F101*G101 -> 0 | I101: =SUM(H52:H101) -> 63577.5
A102: P101 | B102: Preliminary and General Requirements | C102: Sundry ItemsCopies of Orders | D102: Provide the Engineers Representative with a copy of all orders for the supply of such materials or goods required in connection with the Works as the Engineers Representative may specify. | E102: Item | F102: 1 | G102: 0 | H102: =F102*G102 -> 0
A103: P102 | B103: Preliminary and General Requirements | C103: Sundry ItemsWorking Drawings | D103: Allow for preparing and submission to the Engineer of all working drawings and operation and maintenance instructions as detailed in the specification if these costs are not specifically measured elsewhere in the relevant sections of this document. | E103: Item | F103: 1 | G103: 0 | H103: =F103*G103 -> 0
A104: P103 | B104: Preliminary and General Requirements | C104: Sundry ItemsWorking Drawings | D104: Upon completion of the works submit two sets of diskettes Autocad R12 later two transparencies and four copies of all drawings duly marked AsBuilt clearly defining all locations depths shapes and dimensions of all permanent works executed. | E104: Item | F104: 1 | G104: 0 | H104: =F104*G104 -> 0
A105: P104 | B105: Preliminary and General Requirements | C105: Sundry ItemsTraining of Employers Personnel | D105: During the execution of the Works the Contractor shall provide such assistance as may be necessary for the instruction and training of personnel appointed by the Employer. | E105: Item | F105: 1 | G105: 0 | H105: =F105*G105 -> 0
A106: P105 | B106: Preliminary and General Requirements | C106: Sundry ItemsTraining of Employers Personnel | D106: The Contractor shall provide all necessary instruction material for this purpose such as manuals booklets pamphlets drawings sketches models pictures photoscolour slides films etc. This instruction material shall become the property of the Employer. | E106: Item | F106: 1 | G106: 0 | H106: =F106*G106 -> 0
A107: P106 | B107: Preliminary and General Requirements | C107: Sundry ItemsDirect Contractors | D107: The Tenderers attention is drawn to the fact that the Employer may appoint other Contractors to carry out certain items of Specialist Works in accordance with Clause 31 of the Conditions of Contract. | E107: Item | F107: 1 | G107: 0 | H107: =F107*G107 -> 0
A108: P107 | B108: Preliminary and General Requirements Performance Bond Advance Payment Bond and Insurance Certificate | C108: Performance Bond | D108: The Contractor will be required to provide Performance Bond all in accordance with Clause 4.2 of the Conditions of Contract. | E108: Item | F108: 1 | G108: 0 | H108: =F108*G108 -> 0
A109: P108 | B109: Preliminary and General Requirements Performance Bond Advance Payment Bond and Insurance Certificate | C109: Insurance | D109: The Contractor will be required to provide all Insurances in accordance with the Conditions of Contract. | E109: Item | F109: 1 | G109: 0 | H109: =F109*G109 -> 0
A110: P109 | B110: Preliminary and General Requirements Performance Bond Advance Payment Bond and Insurance Certificate | C110: Insurance Declaration | D110: On signing the Contract the Contractor shall obtain from his Insurance Company and lodge with the Engineer a declaration that the insurance provided is strictly in accordance with all relevant Clause in the Conditions of Contract. This shall also include insurance against damage of any kind to existing buildings which may arise as a result of the building operations. | E110: Item | F110: 1 | G110: 0 | H110: =F110*G110 -> 0
A111: P110 | B111: Preliminary and General Requirements Performance Bond Advance Payment Bond and Insurance Certificate | C111: Advance Payment Bond | D111: The Contractor will be required to provide an Advance Payment Bond all in accordance with Clause 14.2 of Conditions of Contract. | E111: Item | F111: 1 | G111: 0 | H111: =F111*G111 -> 0
A112: P111 | B112: Preliminary and General Requirements Temporary Facilities. | C112: Refer Provisional SumTemporary Houses | D112: The Contractor will be required to provide temporary houses Caravan for the resident while working in the Construction and also during Maintenance Works and refix inside houses after work finish as outside extra rooms for them. Every caravan will be around 65m2 and will include and not be limited to 2 rooms a hall a kitchen and two toilets The structure to use steel structure painted with anticorrosion paint with isolated walls and roof aluminum sandwich panels 50 mm thickness from 2 sheets 0.7 mm thickness and foam of 45 kgm3 density internal ceramic floor and walls for toiles and kitchen to be ceramic all sanitary fixture for toilet and kitchen sink and cabinet sewage electrical and water connection to be done in the temporary place and will be finally done again after move to internal new and maintained houses foundation for caravan and 3 steps omani marble in final place fixing also 4 AC are included design of caravan to be done by the contractor approved by clientconsultant beforedelivery the caravans will be under project defects notification period for one year. | E112: item | F112: 0 | G112: 0 | H112: =F112*G112 -> 0
...

Sheet 03 Housing Units
A1: Item Code | B1: Item Name | C1: Item Details | D1: Additional Information | E1: UOM | F1: Quantity | G1: Unit Price | H1: Total Price In Figure | I1: =SUM(H2:H22) -> 947257
A2: C1 | B2: General Works | C2: Demolishing and Clearing the Construction Area | D2: Demolishing the complete building and removing the debris from the Construction Site as per EngineerEmployer Instruction including cart away from the Project Site up to OGL | E2: NO | F2: 20 | G2: 2520 | H2: =F2*G2 -> 50400
A3: C2 | B3: Substructure Works | C3: Site Clearance | D3: This shall include removing vegetation undergrowth bushes hedges trees other temporary buildings structures or the like all complete to clean the full plot. | E3: NO | F3: 20 | G3: 52.5 | H3: =F3*G3 -> 1050
A4: C3 | B4: Substructure Works | C4: Earth work and Excavation | D4: Bulk Excavation to receive foundations in any kind of soil including hard soil and rock earth sport underground surface or running water from whatever source if any for the new foundation building area including removal of old buildings foundations cleaning the site and removing all debris not suitable for backfilling from the project area to the damp yard contractor to prepare all areas to receive new foundation safely as per drawings and soil report. | E4: M3 | F4: 15000 | G4: 0.77 | H4: =F4*G4 -> 11550
A5: C4 | B5: Substructure Works | C5: Filling | D5: Approved imported granular fill material compacted in layers in making up levels under floors | E5: M3 | F5: 4000 | G5: 0.525 | H5: =F5*G5 -> 2100
A6: C5 | B6: Substructure Works | C6: Filling | D6: Approved imported fill material compacted in layers to raise the levels | E6: M3 | F6: 15000 | G6: 0.525 | H6: =F6*G6 -> 7875
A7: C6 | B7: Substructure Works | C7: Filling | D7: Approved selected excavated material backfilled into excavations | E7: M3 | F7: 6000 | G7: 0.525 | H7: =F7*G7 -> 3150
A8: C7 | B8: Substructure Works | C8: Filling | D8: 200 mm thick well compacted hardcore filling under floors | E8: M3 | F8: 1040 | G8: 0.455 | H8: =F8*G8 -> 473.2 | I8: =H5+H6+H7+H8 -> 13598.2 | J8: 13598.2
A9: C8 | B9: Substructure Works | C9: Anti termite treatment | D9: Anti termite treatment to surfaces of ground or filling applied strictly in accordance with the manufacturers printed instructions including digging trenches backfilling etc. as required by the manufacturer and the provision of guarantee valid for 10 years | E9: M2 | F9: 6200 | G9: 1.524 | H9: =F9*G9 -> 9448.8
A10: C9 | B10: Substructure Works | C10: Poured Concrete Plain insitu concrete poured Ordinary Portland Cement OPC Concrete Grade C15 all in accordance with Drawings and Specifications and including Formwork to give as struck finish. Providing and erecting formwork including all necessary staging centering shuttering supports cross bracing deshuttering carefully making good the damaged surfaces wherever necessary all complete as specified and as directed by the Engineer all in accordance with the Drawings and Specifications | D10: Blinding upto 100 mm thickness | E10: M3 | F10: 300 | G10: 63 | H10: =F10*G10 -> 18900 | I10: =H10+H11+H12+H13+H14 -> 245700 | J10: concrete work
A11: C10 | B11: Substructure Works | C11: Reinforced insitu concrete poured vibrated Sulphate Resistent Cement OPC Concrete Grade C30 all in accordance with Drawings and Specifications and including Reinforcement High yield strength deformed bars conforming to BS 4449 Grade 460 including cutting bending binding binding wire cover blocks tests and all necessary fixing accessories all in accordance with the Drawings and Specifications and including Formwork to give as struck finish. Providing and erecting formwork including all necessary staging centering shuttering supports cross bracing deshuttering carefully making good the damaged surfaces wherever necessary all complete as specified and as directed by the Engineer all in accordance with the Drawings and Specifications | D11: Footings | E11: M3 | F11: 800 | G11: 94.5 | H11: =F11*G11 -> 75600
A12: C11 | B12: Substructure Works | C12: Reinforced insitu concrete poured vibrated Sulphate Resistent Cement OPC Concrete Grade C30 all in accordance with Drawings and Specifications and including Reinforcement High yield strength deformed bars conforming to BS 4449 Grade 460 including cutting bending binding binding wire cover blocks tests and all necessary fixing accessories all in accordance with the Drawings and Specifications and including Formwork to give as struck finish. Providing and erecting formwork including all necessary staging centering shuttering supports cross bracing deshuttering carefully making good the damaged surfaces wherever necessary all complete as specified and as directed by the Engineer all in accordance with the Drawings and Specifications | D12: Plinth beams | E12: M3 | F12: 600 | G12: 94.5 | H12: =F12*G12 -> 56700
A13: C12 | B13: Substructure Works | C13: Reinforced insitu concrete poured vibrated Sulphate Resistent Cement OPC Concrete Grade C30 all in accordance with Drawings and Specifications and including Reinforcement High yield strength deformed bars conforming to BS 4449 Grade 460 including cutting bending binding binding wire cover blocks tests and all necessary fixing accessories all in accordance with the Drawings and Specifications and including Steel fabric reinforcement A 393 BRC mesh in two layers. All complete in accordance with the Drawings and Specifications and including Formwork to give as struck finish. Providing and erecting formwork including all necessary staging centering shuttering supports cross bracing deshuttering carefully making good the damaged surfaces wherever necessary all complete as specified and as directed by the Engineer all in accordance with the Drawings and Specifications | D13: Beds Slabs Grade slabs upto 120 mm thickness | E13: M3 | F13: 800 | G13: 94.5 | H13: =F13*G13 -> 75600 | I13: 75600
A14: C13 | B14: Substructure Works | C14: Reinforced insitu concrete poured vibrated ordinary Portland Cement OPC Concrete Grade C40 all in accordance with Drawings and Specifications and including Reinforcement High yield strength deformed bars conforming to BS 4449 Grade 460 including cutting bending binding binding wire cover blocks tests and all necessary fixing accessories all in accordance with the Drawings and Specifications and including Formwork to give as struck finish. Providing and erecting formwork including all necessary staging centering shuttering supports cross bracing deshuttering carefully making good the damaged surfaces wherever necessary all complete as specified and as directed by the Engineer all in accordance with the Drawings and Specifications | D14: Substructure columns | E14: M3 | F14: 200 | G14: 94.5 | H14: =F14*G14 -> 18900
A15: C14 | B15: Substructure Works | C15: Sundries Concrete and Block work Protection | D15: Polythene sheet gauge 1200 all in accordance with Drawings and Specifications to surfaces of structural members in contact with soil | E15: M2 | F15: 8400 | G15: 2 | H15: =F15*G15 -> 16800
A16: C15 | B16: Substructure Works | C16: Sundries Bitumenous Paint | D16: Bitumenous Paint 3 coat to the surfaces of concrete | E16: M2 | F16: 10000 | G16: 0.546 | H16: =F16*G16 -> 5460
A17: C16 | B17: Substructure Works | C17: Sundries Bitumenous Sheet | D17: Bitumenous Sheet to the surfaces of concrete | E17: M2 | F17: 5200 | G17: 5.25 | H17: =F17*G17 -> 27300 | J17: 27300
A18: C17 | B18: Substructure Works | C18: Sundries Block work Protection including Bitumenous Paint and Bitumenous Sheet | D18: Protection to concrete masonryblock work in contact with soil 3 coats of approved bituminous paint bituminous sheet and including flexible board all in accordance with Drawings and Specifications to surfaces of block work in contact with soil. | E18: M2 | F18: 22000 | G18: 21 | H18: =F18*G18 -> 462000 | J18: =462000+H19 -> 565950
A19: C18 | B19: Substructure Works | C19: Concrete solid block work 10.5N per mm2 compressive strength cement and sand mortar 1to3 with and including stiffener columns and stiffener beams as required all in accordance with Drawings and Specifications | D19: 200mm thick walls | E19: M2 | F19: 11000 | G19: 9.45 | H19: =F19*G19 -> 103950 | I19: 103950
A20: C19 | B20: Substructure Works | C20: The Contractor should read and quote as per the supply laying and all works are included and required approval and commissioning as per contract standards should be under the Contractor scope of work including required charges also including DNP scope and guarantees for material. | D20: Important Note | E20: Item | F20: 0 | G20: 0 | H20: =F20*G20 -> 0
A21: C20 | B21: Substructure Works | C21: The Contractor is adviced to complete the project as per the drawing boq and specification also need to complete if anything missing in the drawing but mentioned in the boq and specification and viceversa. Should the Tenderer fail to insert any item here it will be deemed that this lump sum price for the tender includes all items and no subsequent claim for any additional items will be entertained | D21: Important Note | E21: Item | F21: 0 | G21: 0 | H21: =F21*G21 -> 0
A22: C21 | B22: Substructure Works | C22: The Contractor is to detail below any additional items with quantities and rates not previously included to complete the build up of the lump sum tender price for this section of the works. Should the Tenderer fail to insert any item here it will be deemed that this lump sum price for the tender includes all items and no subsequent claim for any additional items will be entertained | D22: Important Note | E22: Item | F22: 0 | G22: 0 | H22: =F22*G22 -> 0
A23: C22 | B23: Superstructure Works Concrete Works | C23: Poured Concrete Reinforced insitu concrete poured vibrated Ordinary Portland Cement OPC concrete grade C30 all in accordance with the Drawings and Specifications and including Reinforcement High yield strength deformed bars conforming to BS 4449 Grade 460 including cutting bending binding binding wire cover blocks tests and all necessary fixing accessories all in accordance with the Drawings and Specifications and including Formwork to give as struck finish. Providing and erecting formwork including all necessary staging centering shuttering supports cross bracing deshuttering carefully making good the damaged surfaces wherever necessary all complete as specified and as directed by the Engineer all in accordance with the Drawings and Specifications | D23: Suspended slabs waist slabs landingsstair etc. not exceeding 200 mm thickness | E23: M3 | F23: 1400 | G23: 10.08 | H23: =F23*G23 -> 14112
A24: C23 | B24: Superstructure Works Concrete Works | C24: Poured Concrete Reinforced insitu concrete poured vibrated Ordinary Portland Cement OPC Concrete Grade C30 all in accordance with the Drawings and Specifications and including Reinforcement High yield strength deformed bars conforming to BS 4449 Grade 460 including cutting bending binding binding wire cover blocks tests and all necessary fixing accessories all in accordance with the Drawings and Specifications and including Formwork to give as struck finish. Providing and erecting formwork including all necessary staging centering shuttering supports cross bracing deshuttering carefully making good the damaged surfaces wherever necessary all complete as specified and as directed by the Engineer all in accordance with the Drawings and Specifications | D24: Columns | E24: M3 | F24: 380 | G24: 13.153 | H24: =F24*G24 -> 4998.14
A25: C24 | B25: Superstructure Works Concrete Works | C25: Poured Concrete Reinforced insitu concrete poured vibrated Ordinary Portland Cement OPC Concrete Grade C30 all in accordance with the Drawings and Specifications and including Reinforcement High yield strength deformed bars conforming to BS 4449 Grade 460 including cutting bending binding binding wire cover blocks tests and all necessary fixing accessories all in accordance with the Drawings and Specifications and including Formwork to give as struck finish. Providing and erecting formwork including all necessary staging centering shuttering supports cross bracing deshuttering carefully making good the damaged surfaces wherever necessary all complete as specified and as directed by the Engineer all in accordance with the Drawings and Specifications | D25: Beams | E25: M3 | F25: 650 | G25: 8.53 | H25: =F25*G25 -> 5544.5
A26: C25 | B26: Superstructure Works Concrete Works | C26: Poured Concrete Reinforced insitu concrete poured vibrated Ordinary Portland Cement OPC Concrete Grade C30 all in accordance with the Drawings and Specifications and including Reinforcement High yield strength deformed bars conforming to BS 4449 Grade 460 including cutting bending binding binding wire cover blocks tests and all necessary fixing accessories all in accordance with the Drawings and Specifications and including Formwork to give as struck finish. Providing and erecting formwork including all necessary staging centering shuttering supports cross bracing deshuttering carefully making good the damaged surfaces wherever necessary all complete as specified and as directed by the Engineer all in accordance with the Drawings and Specifications | D26: Ramp | E26: M3 | F26: 200 | G26: 1.26 | H26: =F26*G26 -> 252
A27: C26 | B27: Superstructure Works Concrete Works | C27: Sundries | D27: GRC Mesh in the Duct 300 X 400 refer to the Architectural Drawing. | E27: NO | F27: 20 | G27: 21 | H27: =F27*G27 -> 420 | I27: =H27+H28+H29 -> 1260 | J27: GRC MESH
A28: C27 | B28: Superstructure Works Concrete Works | C28: Sundries | D28: GRC Mesh in the Duct 300 X 500 refer to the Architectural Drawing. | E28: NO | F28: 20 | G28: 21 | H28: =F28*G28 -> 420
A29: C28 | B29: Superstructure Works Concrete Works | C29: Sundries | D29: GRC Mesh in the Duct 300 X 1000 refer to the Architectural Drawing. | E29: NO | F29: 20 | G29: 21 | H29: =F29*G29 -> 420
A30: C29 | B30: Superstructure Works Concrete Works | C30: Sundries | D30: Planter box including excavation backfilling disposals blinding solid blockwork waterproofing plaster all complete of various size | E30: No | F30: 100 | G30: 47.25 | H30: =F30*G30 -> 4725 | I30: =H30 -> 4725 | J30: PLANTER BOX
A31: C30 | B31: Superstructure Works Masonry | C31: Internal Walls Ordinary Portland cement concrete blocks 7.5N per mm2 compressive strength cement and sand mortar 1to3 with and including stiffener columns and stiffener beams as required all in accordance with the Drawings and Specifications | D31: 200mm thick walls | E31: M2 | F31: 17400 | G31: 15 | H31: =F31*G31 -> 261000 | I31: =H31 -> 261000 | J31: BLOCK WORK
A32: C31 | B32: Superstructure Works Masonry | C32: Sunken Slab Waterproofing | D32: Providing and applying Sunken Slab Waterproof course with bituminous paint and bituminous membrane conforming to BSto6398 in horizontal joints laid strictly in compliance with approved manufacturers printed instructions and as directed by Engineer. | E32: M2 | F32: 700 | G32: 3.6 | H32: =F32*G32 -> 2520 | I32: =H32+H33+H34+H35+H36+H37 -> 37905 | J32: WATER PROOFING
B33: Superstructure Works Masonry | C33: Roof Slab Waterproofing THERMAL AND MOISTURE PROTECTION COVERINGS AND LININGS | D33: Combo roof treatment for thermal and moisture protection for open terraces by an approved expert agency complete with thermal and moisture resistant layers UV protection layer leveling course separation layers top finishes skirting with 250mm high etc. ensuring smooth runoff and with minimum 25 years of warranty. | E33: Item | F33: 1 | G33: 15750 | H33: =F33*G33 -> 15750
A34: C33 | B34: Superstructure Works Thermal and Moisture Protection | C34: Backgrounds and Finishes Roof screed light weight concrete screed 1000 kg per m3 minimum 50 mm thick to a maximum of 125 mm thick | D34: 50 mm minimum bed laid on concrete to falls and cross falls | E34: M2 | F34: 5600 | G34: 1.05 | H34: =F34*G34 -> 5880
A35: C34 | B35: Superstructure Works Thermal and Moisture Protection | C35: 4 mm thick torch applied acrylic polypropylene modified bitumen membrane with non woven polyester reinforcement and polyethylene film waterproof membrane including primer to roofs as per the manufacturer printed instructions complete as specified. Contractor to allow for 10 years guarantee and 24 hours flood test. | D35: To roof decks 4mm thick on flat surface laid to falls and cross falls | E35: M2 | F35: 5600 | G35: 1.05 | H35: =F35*G35 -> 5880
A36: C35 | B36: Superstructure Works Thermal and Moisture Protection | C36: Skirting 300 mm girth including turning into groove | D36: In up standsdrops and around plinths minimum 300 mm high including dressing over fillet grooves sealant tantalized batten etc. complete to roof deck | E36: M | F36: 1900 | G36: 1.05 | H36: =F36*G36 -> 1995
A37: C36 | B37: Superstructure Works Thermal and Moisture Protection | C37: Insulation Extruded high density polystyrene foam board insulation with rigid closed cell structure all in accordance with the specifications and drawings in external | D37: to roof decks 50 mm thick laid on concrete spot bonded to waterproofing | E37: M2 | F37: 5600 | G37: 1.05 | H37: =F37*G37 -> 5880
A38: C37 | B38: Superstructure Works Thermal and Moisture Protection | C38: Roof Finishes | D38: 300 x 300 x 30 mm white cement tiles bedded on and including cement mortar screed to falls and cross falls jointed in cement mortar movements joints etc. complete to roof | E38: M2 | F38: 5600 | G38: 4.2 | H38: =F38*G38 -> 23520
A39: C38 | B39: Superstructure Works Thermal and Moisture Protection | C39: Roof Finishes | D39: 100 x 30 mm white cement skirting to upstands | E39: M | F39: 1900 | G39: 3.15 | H39: =F39*G39 -> 5985
A40: C39 | B40: Superstructure Works Thermal and Moisture Protection | C40: Roof Sundries | D40: Allow for Providing dressing around 110mm 83mm UPVC rainwater outlets roof duct gargoyle extract fan soil and vent pipe | E40: NO | F40: 20 | G40: 78.75 | H40: =F40*G40 -> 1575
...

Sheet 04  External Works
A1: Item Code | B1: Item Name | C1: Item Details | D1: Additional Information | E1: UOM | F1: Quantity | G1: Unit Price In Figure | H1: Total Price In Figure
A2: EW1 | B2: External Works General Site Works | C2: Site Preparation | D2: Allow for setting out grading trimming including clearing loose boulders vegetation stones and the like all trees bushes shrubs and undergrowth grub up all roots and burn or remove from site as directed by the Engineer. | E2: Item | F2: 1 | G2: 0 | H2: =F2*G2 -> 0
A3: EW2 | B3: External Works General Site Works | C3: Boundary wall | D3: Allow for the Contractor to prepare RCC foundation column block work plastering and painting as per the Architectural Drawing and as per Engineer Employer Instruction to complete the Boundary Wall. | E3: M | F3: 1775 | G3: 2.1 | H3: =F3*G3 -> 3727.5
A4: EW3 | B4: External Works General Site Works | C4: Wicket Gate | D4: Allow for the Contractor to supply fabricate and installation of single leaf Wicket Gate as per the Architectural Drawing and follow as per Engineer Employer Instructions including anti corrotion epoxy paint. | E4: no | F4: 20 | G4: 105 | H4: =F4*G4 -> 2100
A5: EW4 | B5: External Works General Site Works | C5: Car Entrance Gate | D5: Allow for the Contractor to supply fabricate and installation of single leaf Car Entrance Gate as per the Architectural Drawing and follow as per Engineer Employer Instructions including anti corrotion epoxy paint | E5: no | F5: 20 | G5: 141.75 | H5: =F5*G5 -> 2835
A6: EW5 | B6: External Works General Site Works | C6: Entrance Gate ont only | D6: Allow for the Contractor to supply fabricate and installation of Wicket Gate solid WPC with 10 years garantee as per the Architectural Drawing and follow as per Engineer Employer Instructions including anti corrotion epoxy paint. | E6: Item | F6: 0 | G6: 0 | H6: =F6*G6 -> 0
A7: EW6 | B7: External Works General Site Works | C7: Wicket Gate | D7: Single leaf Wicket Gate solid WPC | E7: Item | F7: 1 | G7: 0 | H7: =F7*G7 -> 0
A8: EW7 | B8: External Works General Site Works | C8: Car Entrance Gate | D8: Single leaf Car Entrance Gate soild WPC | E8: Item | F8: 1 | G8: 0 | H8: =F8*G8 -> 0
A9: EW8 | B9: External Works General Site Works | C9: Entrance Concrete Paver | D9: Allow for the Contractor to prepare Concrete Paver as per the Architectural Drawing and place at the House Main Entrance. | E9: No | F9: 100 | G9: 5.25 | H9: =F9*G9 -> 525
A10: EW9 | B10: External Works General Site Works | C10: Interlock Tile | D10: Allow for connection Asphalt road to the site from the main drawing as per approval | E10: M2 | F10: 13550 | G10: 1.05 | H10: =F10*G10 -> 14227.5
A11: EW10 | B11: External Works General Site Works | C11: Curb Stone | D11: Allow for connection Asphalt road to the site from the main drawing as per approval | E11: M | F11: 1400 | G11: 2.1 | H11: =F11*G11 -> 2940
A12: EW11 | B12: External Works General Site Works | C12: Design and Build Shaded Car Parking of 20 numbers with Solar Panel Canopy | D12: Allow for the Contractor to design and build the Shaded Car Park for houses with Solar Panel Canopy as per Engineer Employer Instruction. | E12: no | F12: 20 | G12: 105 | H12: =F12*G12 -> 2100 | I12: STORM WATER BILL
A13: TOTAL EXTERNAL WORKS AND EXTERNAL SERVICES | G13: =SUM(H2:H12) -> 28455 | I13: =G13+'06 Storm Water'!G44 -> 28455

Sheet 05 Existing Housing Units-29
A1: Item Code | B1: Item Name | C1: Item Details | D1: Additional Information | E1: UOM | F1: Quantity | G1: Unit Price In Figure | H1: Total Price In Figure | I1: demolishing team | J1: Concret Team | K1: helper | L1: Masen | M1: Tielman | N1: draftsman | O1: Painter | P1: electrician | Q1: plumper | R1: steel man | S1: carpenter | T1: AC tec | U1: welder | V1: doorman | W1: windoman | X1: SS work | Y1: Solar | Z1: TV Dish
A2: EX1 | B2: External Works Lump sum | C2: Site Clearance | D2: Which shall include removing vegetation undergrowth bushes hedges trees or the like all complete item also Removal and disposal of surplus excavated material including providing suitable tip to the dumping yard or as specified and directed by the Engineer or local authorities.. | E2: Item | F2: 29 | G2: 304.5 | H2: =F2*G2 -> 8830.5 | I2: Yes | AA2: =SUM(H2:H9) -> 119059.5 | AB2: demolitios
A3: EX2 | B3: External Works Lump sum | C3: Demolishing | D3: demolishing all the structures and stores inside the boundary wall by preparing a sketch for each house and submitting to clients engineer and getting the written approval for demolishing and shifting the disposal material to damp yard including foundations of structres. | E3: Item | F3: 29 | G3: 514.5 | H3: =F3*G3 -> 14920.5 | I3: Yes | N3: Yes | AA3: =SUM(H2:H18) -> 452152.05 | AB3: till super structure
A4: EX3 | B4: External Works Lump sum | C4: Demolishing Rebuild | D4: demolishing and rebuilding as per the Same Specifications the gates columns damaged boundary wall damaged manholes damaged Holding Tanks damaged Sock Pits and change the cover to be GRP type Heavy duty and any other elements must be demolished to modified or rebuilt as per main scope all of this including and not limited to Excavation in any type of soil Disposal of surplus material filling by imported fill material compacted in layers waterproof concrete reinforcements joints block works polythene sheets anti termite manholes cover plastering PVC Pipes and any necessary work to finish the work in functional condition. | E4: Item | F4: 29 | G4: 619.5 | H4: =F4*G4 -> 17965.5 | I4: Yes | J4: Yes | L4: Yes | Q4: Yes
A5: EX4 | B5: External Works Lump sum | C5: boundary wall | D5: the contractor has to remove and demolish any damaged or unsafe parts of the wall and rebuild it with the same height after filling any cracks space between concreet and blockwork with non shirenkage filler with SS mesh between concrete and blocks and to remove all the paint or cladding and re paint again with external paint weather coat stoneshield with prime coat with 10 years garantee .all of this including and not limitted to to 200mm thick walls Polythene sheet gauge 1000 Waterproofing with two bitumen coats and membrane 4mm to surfaces of concreteProtection to concretemasonryblock work in contact with soil 3 coats approved bituminous paintExpansion joint | E5: Item | F5: 29 | G5: 619.5 | H5: =F5*G5 -> 17965.5 | I5: Yes | L5: Yes | O5: Yes
A6: EX5 | B6: External Works Lump sum | C6: GI gates | D6: remove the existing gates and supply and fix new gates GI and painted with marine paint as per the site conditions with warranty for the paint and gates for 10 years | E6: Item | F6: 29 | G6: 724.5 | H6: =F6*G6 -> 21010.5
A7: EX6 | B7: External Works Lump sum | C7: Pea Gravel around the house and inside the boundary wall | D7: the contractor has fill the full area with pea gravel with size between 20mm to 50mm max with depth 100 mm around the house detecting from it the manholes and holding tanks and sock pit only but it must be under the new caravans | E7: Item | F7: 29 | G7: 829.5 | H7: =F7*G7 -> 24055.5 | K7: Yes
A8: EX7 | B8: External Works Lump sum | C8: Dewatering | D8: Allow for keeping excavations free from underground surface or running water from whatever source | E8: Item | F8: 29 | G8: 252 | H8: =F8*G8 -> 7308 | Q8: Yes
A9: EX8 | B9: External Works Lump sum | C9: Gas Cylinder Room | D9: Contractor has to built a Gas Cylinder Room with RCC base and block work with height 1.5 m with concrete top slab with suitable foundation and safety gate that powder coated and painted with marine paint with warranty 10 years. | E9: Item | F9: 29 | G9: 241.5 | H9: =F9*G9 -> 7003.5 | L9: Yes
A10: C1 | B10: Super Structure Works Lump sum | C10: Demolishing the Existing staircase slab and reconstract it with Poured Concrete Reinforced insitu concrete poured vibrated Ordinary Portland Cement OPC concrete grade C35 all in accordance with the Drawings and Specifications including but not limited formwork reinforcement additives movement joints construction joints joint filler curing compounds surface finishes water stop wherever necessary concrete tests and any other accessories and ancillary work required to complete the work. | D10: RCC slabs RCC beams RCC Columns landingsstair etc. not exceeding 200 mm thickness at staircase head rooms. | E10: Item | F10: 29 | G10: 262.5 | H10: =F10*G10 -> 7612.5 | I10: Yes | J10: Yes | L10: Yes | O10: Yes | P10: Yes | R10: Yes | S10: Yes
A11: C2 | B11: Superstructure Works Thermal and Moisture Protection | C11: Removing Roof tiles and screed and waterproofing with cleaning the surfaces closing any cracks with chemical sealants and making the surface ready for receiving the new waterproofing. | D11: Demolishing the existing roof finish with waterproof and disposal the material and make the surface ready for receiving the new waterproofing | E11: Item | F11: 29 | G11: 1995 | H11: =F11*G11 -> 57855 | I11: Yes
A12: C3 | B12: Superstructure Works Thermal and Moisture Protection | C12: Roof screed lightweight concrete screed 1000 kgm3 minimum 50 mm thick to a maximum of 125 mm thick and Waterproofing with two bitumen coats and 4 mm thick torch applied acrylic polypropylene modified bitumen membrane with nonwoven polyester reinforcement and polyethylene film waterproof membrane including primer to roofs as per the manufacturer printed instructions complete as specified. Contractor to allow for 10 years guarantee and 24 hours flood test | D12: To roof decksRoof screed lightweight concrete screed 1000 kgm3 minimum 50 mm thick to a maximum of 125 mm thick and Waterproofing with two bitumen coats and 4mm thick membrane on flat surface laid to falls and cross falls | E12: Item | F12: 29 | G12: 3150 | H12: =F12*G12 -> 91350 | J12: Yes | L12: Yes
A13: C4 | B13: Superstructure Works Thermal and Moisture Protection | C13: Skirting 300 mm girth including turning into groove | D13: In up standsdrops and around parapet minimum 300 mm high including dressing over fillet grooves sealant tantalized batten etc. complete to roof deck | E13: Item | F13: 29 | G13: 1890 | H13: =F13*G13 -> 54810 | J13: Yes | L13: Yes
A14: C5 | B14: Superstructure Works Thermal and Moisture Protection | C14: Insulation Extruded high density polystyrene foam board insulation with rigid closed cell structure all in accordance with the specifications and drawings external | D14: to roof decks 50 mm thick laid on concrete spot bonded to waterproofing | E14: Item | F14: 29 | G14: 514.5 | H14: =F14*G14 -> 14920.5
A15: C6 | B15: Superstructure Works Thermal and Moisture Protection | C15: Roof Finishes | D15: Supply and fix 300 x 300 x 25 mm terrazzo tiles bedded on and including cement mortar screed to falls and cross falls jointed in cement mortar movements joints etc. complete to roof | E15: Item | F15: 29 | G15: 1995 | H15: =F15*G15 -> 57855 | M15: Yes
A16: C7 | B16: Superstructure Works Thermal and Moisture Protection | C16: Roof Finishes | D16: Supply and fix 100x20 mm terrazzo skirting to upstands | E16: Item | F16: 29 | G16: 892.5 | H16: =F16*G16 -> 25882.5 | M16: Yes | AA16: =H16+H13 -> 80692.5
A17: C8 | B17: Superstructure Works Thermal and Moisture Protection | C17: Roof Sundries | D17: Allow for Providing dressing around 110mm83mm UPVC rainwater outlets roof duct gargoyle extract fan soil and vent pipe | E17: Item | F17: 29 | G17: 481.95 | H17: =F17*G17 -> 13976.55 | M17: Yes | Q17: Yes
A18: C9 | B18: Superstructure Works Thermal and Moisture Protection | C18: Roof Sundries | D18: For parapet Allow for gun applied sealant to seal the joints and groove as applicable and as specified. | E18: Item | F18: 29 | G18: 304.5 | H18: =F18*G18 -> 8830.5 | M18: Yes
A19: C10 | B19: Superstructure Works Metal Works | C19: Staircase handrail | D19: Removing the old handrails and replacing them with 316 St.st handrails including supply and fix as per exixting desin hand rail in new houses drawings. | E19: Item | F19: 29 | G19: 1575 | H19: =F19*G19 -> 45675 | I19: Yes | X19: Yes | AA19: =H19+H20 -> 53287.5
A20: C11 | B20: Superstructure Works Metal Works | C20: galvanized steel cat Ladder | D20: Supply and install galvanized steel cat Ladder as specified and detailed on the drawingas per exixting desin hand rail in new houses drawings. | E20: Item | F20: 29 | G20: 262.5 | H20: =F20*G20 -> 7612.5 | U20: Yes
