Workbook

Sheet GRANT SUMMARY
B2: CONSTRUCTION, COMPLETION AND MAINTENANCE OF PROPOSED (20NOS) HOUSING UNITS AND MAINTENANCE WORKS FOR THE EXISTING (32) HOUSES FOR THE MINISTRY
B3: GRAND SUMMARY
B4: Priced Bill Of Quantities
B5: Transfer the Contract Summary of Contract Value to the Form of Tender
B7: S/N | C7: BILL NO | D7: DESCRIPTION | E7: BOQ AMOUNT | F7: BOQ AMOUNT | G7: REVISED VALUE AFTER V.O 1 | H7: Addition | I7: Omission | J7: Savings Excluding V.O 1 | K7: EXPECTED REVISED BOQ VALUE AFTER A/O | M7: ADDITION AMOUNT/VARIATION | N7: SAVING AMOUNT | O7: % | R7: CLAUSES | S7: Appendix
B9: 1 | C9: BILL NO 1 | D9: PRELIMINARIES | E9: =F9 -> 227580 | F9: =SUMMARY!D4 -> 227580 | G9: =F9 -> 227580 | H9: 224532 | I9: 124800 | J9: =I9-H9 -> -99732 | K9: =F9-J9 -> 327312 | L9: =K9-F9 -> 99732 | N9: =F9-K9 -> -99732 | O9: =J9/F9*100 -> -43.822832 | P9: =K9/$K$45 -> 0.085451923 | Q9: =P9 -> 0.085451923 | S9: Bill No 1. (PRELIMINARIES)
H10: 0 | I10: 124800 | J10: 124800 | K10: 102780
B12: 2 | C12: BILL NO 2 | D12: DAY WORKS | E12: =F12 -> 88252.5 | F12: =SUMMARY!D6 -> 88252.5 | G12: =F12 -> 88252.5 | I12: 88252.5 | J12: =I12-H12 -> 88252.5 | K12: =F12-J12 -> 0 | L12: =J12-K12 -> 88252.5 | N12: =SUMMARY!G6 -> 88262.5 | O12: =J12/F12*100 -> 100 | P12: =K12/$K$45 -> 0 | Q12: =P12 -> 0 | S12: Bill No 2. (DAY WORK)
B15: 3 | C15: BILL NO 3 | D15: PROVISIONAL SUM | E15: =F15 -> 200000 | F15: 200000 | I15: 200000 | J15: =I15-H15 -> 200000 | L15: =K15-J15 -> -200000 | N15: =F15-K15 -> 200000 | O15: =J15/F15*100 -> 100 | P15: =K15/$K$45 -> 0 | S15: Bill No 3. (PROVISIONAL SUM)
B17: 4 | C17: BILL NO 4 | D17: NEW HOUSING UNIT (20 UNITS) | E17: =F19+F22 -> 1965370.9 | Q17: =SUM(P19,P22) -> 0.42164429
D19: SUBSTRUCTURE WORKS | F19: =SUMMARY!D11 -> 947257 | G19: =F19 -> 947257 | H19: ='20 NHU ADD. QTY'!H33 -> 41896.539 | I19: =SUMMARY!G11 -> 291914.71 | J19: =I19-H19 -> 250018.17 | K19: =F19-J19 -> 697238.83 | L19: =J19-K19 -> -447220.66 | N19: =SUMMARY!G11 -> 291914.71 | O19: =J19/F19*100 -> 26.393911 | P19: =K19/$K$45 -> 0.18202938 | R19: 12.1 | S19: 20 NEW ADD QTY | W19: =G19-635463.746 -> 311793.25
H20: 0 | I20: 311793.25 | J20: 311793.25 | K20: 635463.75
D22: SUPERSTRUCTURE WORKS | F22: =SUMMARY!D21 -> 1018113.9 | G22: =F22 -> 1018113.9 | H22: =SUMMARY!H21 -> 23100 | I22: =SUMMARY!G21 -> 123401.5 | J22: =I22-H22 -> 100301.5 | K22: =F22-J22 -> 917812.44 | L22: =K22-J22 -> 817510.94 | M22: =SUMMARY!H21 -> 23100 | N22: =SUMMARY!G21 -> 123401.5 | O22: =J22/F22*100 -> 9.851697 | P22: =K22/$K$45 -> 0.23961492 | R22: 12.2 | S22: GRAND SUM. ADD. (Bill No. 4 & 7)
H23: 0 | I23: 85157 | J23: 85157 | K23: 932956.94
B25: 5 | C25: BILL NO 4 | D25: EXTERNAL WORKS AND EXTERNAL SERVICES | E25: =F25 -> 28455 | F25: =SUMMARY!D27 -> 28455 | G25: =F25 -> 28455 | H25: 0 | I25: =SUMMARY!G27 -> 2100 | J25: =I25-H25 -> 2100 | K25: =F25-J25 -> 26355 | L25: =K25 -> 26355 | N25: =SUMMARY!G27 -> 2100 | O25: =J25/F25*100 -> 7.3800738 | P25: =K25/$K$45 -> 0.0068805465 | Q25: =P25 -> 0.0068805465 | S25: BIll No 4 (20 NHI EXXTERNAL WORK)
I26: 0 | J26: 0 | K26: 28455
B28: 6 | C28: BILL NO 5 | D28: MAINTENANCE WORKS FOR THE EXISTING HOUSING UNITS (29 NO) | E28: =F28 -> 1436308.6 | F28: =SUMMARY!D13 -> 1436308.6 | G28: =F28 -> 1436308.6 | H28: =SUMMARY!H13 -> 11890 | I28: =SUMMARY!G13 -> 9991.805 | J28: =I28-H28 -> -1898.195 | K28: =F28-J28 -> 1438206.8 | L28: =K28-J28 -> 1440105 | M28: =SUMMARY!H13 -> 11890 | N28: =SUMMARY!G13 -> 9991.805 | O28: =J28/F28*100 -> -0.13215788 | P28: =K28/$K$45 -> 0.37547519 | Q28: =P28 -> 0.37547519 | R28: 12.2 | S28: ADD. WORK (29 - MHU)
H29: 43723 | I29: 9991.8 | J29: -33731.8 | K29: 1470040.4
B32: 7 | C32: BILL NO 6 | D32: PROTECTION AND STORM WATER DRAINAGE | E32: =F32 -> 265674.67 | F32: =SUMMARY!D16 -> 265674.67 | G32: =F32 -> 265674.67 | H32: ='BILL NO 6 (STORM WATER)'!O36 -> 11318 | I32: ='BILL NO 6 (STORM WATER)'!J35 -> 70280.7 | J32: =I32-H32 -> 58962.7 | K32: =F32-J32 -> 206711.97 | L32: =J32-K32 -> -147749.27 | N32: =F32-K32 -> 58962.7 | O32: =J32/F32*100 -> 22.193572 | P32: =K32/$K$45 -> 0.053966661 | Q32: =P32 -> 0.053966661 | S32: ADD. WORK ON CHANNEL
H33: 0 | I33: 103282.2 | J33: 103282.2 | K33: 162392.48
B35: 8 | C35: BILL NO 7 | D35: 3 NUMBER HOUSING UNITS | E35: =F37+F40 -> 239991.02 | Q35: =SUM(P37,P40) -> 0.056581382
D37: SUBSTRUCTURE WORKS | F37: =SUMMARY!D18 -> 36105 | G37: =F37 -> 36105 | H37: ='20 NHU ADD. QTY'!H62 -> 11250 | I37: =SUMMARY!G18 -> 10515.156 | J37: =I37-H37 -> -734.844 | K37: =F37-J37 -> 36839.844 | L37: =K37-J37 -> 37574.688 | N37: =SUMMARY!G18 -> 10515.156 | O37: =J37/F37*100 -> -2.0352971 | P37: =K37/$K$45 -> 0.0096178433 | R37: 12.1 | S37: 20 NHU ADD. QTY/ Bill No 7. (3 NHU)
H38: 0 | I38: 10515.096 | J38: 10515.096 | K38: 25589.904
D40: SUPERSTRUCTURE WORK | F40: =SUMMARY!D23 -> 203886.02 | G40: =F40 -> 203886.02 | H40: ='SUM. OF ADD. WORKS (BILL NO. 4 '!G17 -> 1111.44 | I40: =SUMMARY!G23 -> 25110 | J40: =I40-H40 -> 23998.56 | K40: =F40-J40 -> 179887.46 | L40: =K40-J40 -> 155888.9 | M40: =SUMMARY!H23 -> 1111.44 | N40: =SUMMARY!G23 -> 25110 | O40: =J40/F40*100 -> 11.770576 | P40: =K40/$K$45 -> 0.046963539 | R40: 12.2 | S40: SUM. OF ADD. WORKS (Bill No 4 & 7)
I41: 12000 | J41: 12000 | K41: 204997.44
P42: =SUM(P40,P38,P37,P36,P35,P33,P32,P31,P28,P27,P25,P23,P22,P21,P19,#REF!,P17,P16,P15,P14,P12,P11,P9) -> #REF! | Q42: =SUM(Q40,Q38,Q37,Q36,Q35,Q33,Q32,Q31,Q28,Q27,Q25,Q23,Q22,Q21,Q19,#REF!,Q17,Q16,Q15,Q14,Q12,Q11,Q9) -> #REF!
O43: =N45+M45 -> 746627.81
B45: Total Contract Value | E45: =SUM(E9:E41) -> 4451632.7 | F45: =SUM(F9:F40) -> 4451632.7 | G45: =SUM(G9+G12+G19+G22+G25+G28+G32+G37+G40) -> 4251632.7 | H45: =SUM(H9+H12+H19+H22+H28+H32+H37+H40) -> 325097.98 | I45: =SUM(I9+I12+I19+I22+I25+I28+I32+I37+I40) -> 746366.37 | J45: =SUM(J9+J12+J19+J22+J25+J28+J32+J37+J40+J15) -> 621268.39 | K45: =SUM(K9+K12+K19+K22+K25+K28+K32+K37+K40) -> 3830364.4 | L45: =F45-K45 -> 621268.39 | M45: =SUM(M9:M40) -> 36101.44 | N45: =SUM(N9:N44) -> 710526.37
H48: =I45-H45 -> 421268.39 | K48: =F45-K45 -> 621268.39 | N48: =SUM(N45:N47) -> 710526.37
L49: =I45+J45 -> 1367634.8
F50: CONTRACT PRICE | K50: CLAIMABLE | N50: ADD/OMISSION IMPACT | P50: =328588.41+7678.88 -> 336267.29 | R50: =55*355 -> 19525
P51: =P50-220352 -> 115915.29 | R51: =R50*32 -> 624800 | S51: =R51+K45 -> 4455164.4
D52: PERCENTAGE | F52: AMOUNT | K52: PERCENTAGE | L52: =J45+K48 -> 1242536.8 | N52: =O43-F48 -> 746627.81
C54: Addition/Omission and Change Order Impact | D54: CONTRACT TOTAL VALUE | F54: =F45 -> 4451632.7 | K54: =F54/F54 -> 1 | L54: =H49-J49 -> 0 | S54: =F45-S51 -> -3531.6095
D55: CLAIMABLE TOTAL AMOUNT | F55: =K45 -> 3830364.4 | K55: =F55/F54 -> 0.86044033
D56: ADDITION OMMISSION IMPACT | F56: =N48 -> 710526.37 | K56: =F56/F54 -> 0.15961028
D57: ADDITIONAL WORK BILL NO. 5 | F57: =SUMMARY!H23 -> 1111.44 | K57: =(F57+F58)/F54 -> 0.049748812 | N57: =F57+F58 -> 221463.44
D58: CHANGE ORDER -2 | F58: 220352
D59: NET FINANCIAL IMPACT | F59: =F54*K59 -> 4051827.8 | K59: =K55+K57 -> 0.91018914
C60: Progress Impact | D60: OVERALL FINANCIAL IMPACT | K60: =K54-K59 -> 0.089810857
...

Sheet Copy of Copy of GRANT SUMMARY
B2: CONSTRUCTION, COMPLETION AND MAINTENANCE OF PROPOSED (20NOS) HOUSING UNITS AND MAINTENANCE WORKS FOR THE EXISTING (32) HOUSES FOR THE MINISTRY
B3: GRAND SUMMARY
B4: Priced Bill Of Quantities
B5: Transfer the Contract Summary of Contract Value to the Form of Tender
B7: S/N | C7: BILL NO | D7: DESCRIPTION | E7: BOQ AMOUNT | F7: BOQ AMOUNT | G7: REVISED VALUE AFTER V.O 1 | H7: Addition | I7: Omission | J7: Savings Excluding V.O 1 | K7: EXPECTED REVISED BOQ VALUE AFTER A/O | M7: ADDITION AMOUNT/VARIATION | N7: SAVING AMOUNT | O7: % | R7: CLAUSES | S7: Appendix
B9: 1 | C9: BILL NO 1 | D9: PRELIMINARIES | E9: =F9 -> 227580 | F9: =SUMMARY!D4 -> 227580 | G9: =F9 -> 227580 | H9: 0 | I9: 124800 | J9: =I9-H9 -> 124800 | K9: =F9-J9 -> 102780 | L9: =K9-F9 -> -124800 | N9: =F9-K9 -> 124800 | O9: =J9/F9*100 -> 54.837859 | P9: =K9/$K$36 -> 0.028593571 | Q9: =P9 -> 0.028593571 | S9: Bill No 1. (PRELIMINARIES)
B11: 2 | C11: BILL NO 2 | D11: DAY WORKS | E11: =F11 -> 88252.5 | F11: =SUMMARY!D6 -> 88252.5 | G11: =F11 -> 88252.5 | H11: 0 | I11: 88252.5 | J11: =I11-H11 -> 88252.5 | K11: =F11-J11 -> 0 | L11: =J11-K11 -> 88252.5 | N11: =SUMMARY!G6 -> 88262.5 | O11: =J11/F11*100 -> 100 | P11: =K11/$K$36 -> 0 | Q11: =P11 -> 0 | S11: Bill No 2. (DAY WORK)
B14: 3 | C14: BILL NO 3 | D14: PROVISIONAL SUM | E14: =F14 -> 200000 | F14: 200000 | G14: 0 | H14: 0 | I14: 200000 | J14: =I14-H14 -> 200000 | K14: 0 | L14: =K14-J14 -> -200000 | N14: =F14-K14 -> 200000 | O14: =J14/F14*100 -> 100 | P14: =K14/$K$36 -> 0 | S14: Bill No 3. (PROVISIONAL SUM)
B16: 4 | C16: BILL NO 4 | D16: NEW HOUSING UNIT (20 UNITS) | E16: =F18+F20 -> 1965370.9 | Q16: =SUM(P18,P20) -> 0.44931001
D18: SUBSTRUCTURE WORKS | F18: =SUMMARY!D11 -> 947257 | G18: =F18 -> 947257 | H18: ='20 NHU ADD. QTY'!H33 -> 41896.539 | I18: =SUMMARY!G11 -> 291914.71 | J18: =I18-H18 -> 250018.17 | K18: =F18-J18 -> 697238.83 | L18: =J18-K18 -> -447220.66 | N18: =SUMMARY!G11 -> 291914.71 | O18: =J18/F18*100 -> 26.393911 | P18: =K18/$K$36 -> 0.19397303 | R18: 12.1 | S18: 20 NEW ADD QTY
D20: SUPERSTRUCTURE WORKS | F20: =SUMMARY!D21 -> 1018113.9 | G20: =F20 -> 1018113.9 | H20: =SUMMARY!H21 -> 23100 | I20: =SUMMARY!G21 -> 123401.5 | J20: =I20-H20 -> 100301.5 | K20: =F20-J20 -> 917812.44 | L20: =K20-J20 -> 817510.94 | M20: =SUMMARY!H21 -> 23100 | N20: =SUMMARY!G21 -> 123401.5 | O20: =J20/F20*100 -> 9.851697 | P20: =K20/$K$36 -> 0.25533698 | R20: 12.2 | S20: GRAND SUM. ADD. (Bill No. 4 & 7)
B22: 5 | C22: BILL NO 4 | D22: EXTERNAL WORKS AND EXTERNAL SERVICES | E22: =F22 -> 28455 | F22: =SUMMARY!D27 -> 28455 | G22: =F22 -> 28455 | H22: 0 | I22: =SUMMARY!G27 -> 2100 | J22: =I22-H22 -> 2100 | K22: =F22-J22 -> 26355 | L22: =K22 -> 26355 | N22: =SUMMARY!G27 -> 2100 | O22: =J22/F22*100 -> 7.3800738 | P22: =K22/$K$36 -> 0.0073320058 | Q22: =P22 -> 0.0073320058 | S22: BIll No 4 (20 NHI EXXTERNAL WORK)
B24: 6 | C24: BILL NO 5 | D24: MAINTENANCE WORKS FOR THE EXISTING HOUSING UNITS (29 NO) | E24: =F24 -> 1436308.6 | F24: =SUMMARY!D13 -> 1436308.6 | G24: =F24 -> 1436308.6 | H24: =SUMMARY!H13 -> 11890 | I24: =SUMMARY!G13 -> 9991.805 | J24: =I24-H24 -> -1898.195 | K24: =F24-J24 -> 1438206.8 | L24: =K24-J24 -> 1440105 | M24: =SUMMARY!H13 -> 11890 | N24: =SUMMARY!G13 -> 9991.805 | O24: =J24/F24*100 -> -0.13215788 | P24: =K24/$K$36 -> 0.40011158 | Q24: =P24 -> 0.40011158 | R24: 12.2 | S24: ADD. WORK (29 - MHU)
B26: 7 | C26: BILL NO 6 | D26: PROTECTION AND STORM WATER DRAINAGE | E26: =F26 -> 265674.67 | F26: =SUMMARY!D16 -> 265674.67 | G26: =F26 -> 265674.67 | H26: 0 | I26: ='BILL NO 6 (STORM WATER)'!J35 -> 70280.7 | J26: =I26-H26 -> 70280.7 | K26: =F26-J26 -> 195393.97 | L26: =J26-K26 -> -125113.27 | N26: =F26-K26 -> 70280.7 | O26: =J26/F26*100 -> 26.453669 | P26: =K26/$K$36 -> 0.054358936 | Q26: =P26 -> 0.054358936 | S26: ADD. WORK ON CHANNEL
B28: 8 | C28: BILL NO 7 | D28: 3 NUMBER HOUSING UNITS | E28: =F30+F32 -> 239991.02 | Q28: =SUM(P30,P32) -> 0.060293906
D30: SUBSTRUCTURE WORKS | F30: =SUMMARY!D18 -> 36105 | G30: =F30 -> 36105 | H30: ='20 NHU ADD. QTY'!H62 -> 11250 | I30: =SUMMARY!G18 -> 10515.156 | J30: =I30-H30 -> -734.844 | K30: =F30-J30 -> 36839.844 | L30: =K30-J30 -> 37574.688 | N30: =SUMMARY!G18 -> 10515.156 | O30: =J30/F30*100 -> -2.0352971 | P30: =K30/$K$36 -> 0.010248907 | R30: 12.1 | S30: 20 NHU ADD. QTY/ Bill No 7. (3 NHU)
D32: SUPERSTRUCTURE WORK | F32: =SUMMARY!D23 -> 203886.02 | G32: =F32 -> 203886.02 | H32: ='SUM. OF ADD. WORKS (BILL NO. 4 '!G17 -> 1111.44 | I32: =SUMMARY!G23 -> 25110 | J32: =I32-H32 -> 23998.56 | K32: =F32-J32 -> 179887.46 | L32: =K32-J32 -> 155888.9 | M32: =SUMMARY!H23 -> 1111.44 | N32: =SUMMARY!G23 -> 25110 | O32: =J32/F32*100 -> 11.770576 | P32: =K32/$K$36 -> 0.050044998 | R32: 12.2 | S32: SUM. OF ADD. WORKS (Bill No 4 & 7)
P33: =SUM(P32,#REF!,P30,P29,P28,#REF!,P26,P25,P24,P23,P22,#REF!,P20,P19,P18,#REF!,P16,P15,P14,P13,P11,P10,P9) -> #REF! | Q33: =SUM(Q32,#REF!,Q30,Q29,Q28,#REF!,Q26,Q25,Q24,Q23,Q22,#REF!,Q20,Q19,Q18,#REF!,Q16,Q15,Q14,Q13,Q11,Q10,Q9) -> #REF!
O34: =N36+M36 -> 982477.81
B36: Total Contract Value | E36: =SUM(E9:E32) -> 4451632.7 | F36: =SUM(F9:F32) -> 4451632.7 | G36: =SUM(G9+G11+G18+G20+G22+G24+G26+G30+G32) -> 4251632.7 | H36: =SUM(H9+H11+H18+H20+H24+H26+H30+H32+H14) -> 89247.979 | I36: =SUM(I9+I11+I18+I20+I22+I24+I26+I30+I32+I14) -> 946366.37 | J36: =SUM(J9+J11+J18+J20+J22+J24+J26+J30+J32+J14) -> 857118.39 | K36: =SUM(K9+K11+K18+K20+K22+K24+K26+K30+K32) -> 3594514.4 | L36: =F36-K36 -> 857118.39 | M36: =SUM(M9:M32) -> 36101.44 | N36: =SUM(N9:N35) -> 946376.37
H39: =I36-H36 -> 857118.39 | K39: =F36-K36 -> 857118.39 | N39: =SUM(N36:N38) -> 946376.37
L40: =I36+J36 -> 1803484.8
F41: CONTRACT PRICE | K41: CLAIMABLE | N41: ADD/OMISSION IMPACT | P41: =328588.41+7678.88 -> 336267.29 | R41: =55*355 -> 19525
P42: =P41-220352 -> 115915.29 | R42: =R41*32 -> 624800 | S42: =R42+K36 -> 4219314.4
D43: PERCENTAGE | F43: AMOUNT | K43: PERCENTAGE | L43: =J36+K39 -> 1714236.8 | N43: =O34-F39 -> 982477.81
C45: Addition/Omission and Change Order Impact | D45: CONTRACT TOTAL VALUE | F45: =F36 -> 4451632.7 | K45: =F45/F45 -> 1 | L45: =H40-J40 -> 0 | S45: =F36-S42 -> 232318.39
D46: CLAIMABLE TOTAL AMOUNT | F46: =K36 -> 3594514.4 | K46: =F46/F45 -> 0.80745977
D47: ADDITION OMMISSION IMPACT | F47: =N39 -> 946376.37 | K47: =F47/F45 -> 0.21259085
D48: ADDITIONAL WORK BILL NO. 5 | F48: =SUMMARY!H23 -> 1111.44 | K48: =(F48+F49)/F45 -> 0.049748812 | N48: =F48+F49 -> 221463.44
D49: CHANGE ORDER -2 | F49: 220352
D50: NET FINANCIAL IMPACT | F50: =F45*K50 -> 3815977.8 | K50: =K46+K48 -> 0.85720858
C51: Progress Impact | D51: OVERALL FINANCIAL IMPACT | K51: =K45-K50 -> 0.14279142
D52: CLAIMED TO DATE AGAINST CONTRACT | F52: 2193954.4 | K52: =2193954.35/F45 -> 0.49284262 | N52: =(K52+K53)/2 -> 0.55160222
D53: CLAIMED AGAINST CLAIMABLE VALUE | F53: 2193954.4 | K53: =F53/F46 -> 0.61036183
D54: CLAIMABLE AMOUNT - BILL 11 (13-04-26) | F54: 110000 | K54: =F54/F45 -> 0.024710035
K55: =K53-K52+K54 -> 0.14222924 | N55: =69.5%-N52 -> 0.14339778
D56: Progres Against Contract Vs Revised Value | K56: Planned VS Actual Cost | N56: Planned Vs Actual Progress

Sheet 1ST SCENARIOS. BILL 6 ACTUAL
B2: CONSTRUCTION, COMPLETION AND MAINTENANCE OF PROPOSED (20NOS) HOUSING UNITS AND MAINTENANCE WORKS FOR THE EXISTING (32) HOUSES FOR THE MINISTRY
B3: GRAND SUMMARY
B4: Priced Bill Of Quantities
B5: Transfer the Contract Summary of Contract Value to the Form of Tender
B7: S/N | C7: BILL NO | D7: DESCRIPTION | E7: BOQ AMOUNT | F7: BOQ AMOUNT | G7: REVISED VALUE AFTER V.O 1 | H7: Addition | I7: Omission | J7: Savings Excluding V.O 1 | K7: EXPECTED REVISED BOQ VALUE AFTER A/O | L7: AMOUNT CLAIMED AS PER BILL NO. 12 | N7: ADDITION AMOUNT/VARIATION | O7: SAVING AMOUNT | P7: % | S7: CLAUSES | T7: Appendix
B9: 1 | C9: BILL NO 1 | D9: PRELIMINARIES | E9: =F9 -> 227580 | F9: =SUMMARY!D4 -> 227580 | G9: =F9 -> 227580 | H9: 0 | I9: 124800 | J9: =I9-H9 -> 124800 | K9: =F9-J9 -> 102780 | L9: 75255.52 | M9: =K9-F9 -> -124800 | O9: =F9-K9 -> 124800 | P9: =J9/F9*100 -> 54.837859 | Q9: =K9/$K$33 -> 0.030492469 | R9: =Q9 -> 0.030492469 | T9: Bill No 1. (PRELIMINARIES)
B11: 2 | C11: BILL NO 2 | D11: DAY WORKS | E11: =F11 -> 88252.5 | F11: =SUMMARY!D6 -> 88252.5 | G11: =F11 -> 88252.5 | H11: 0 | I11: 88252.5 | J11: =I11-H11 -> 88252.5 | K11: =F11-J11 -> 0 | L11: 0 | M11: =J11-K11 -> 88252.5 | O11: =SUMMARY!G6 -> 88262.5 | P11: =J11/F11*100 -> 100 | Q11: =K11/$K$33 -> 0 | R11: =Q11 -> 0 | T11: Bill No 2. (DAY WORK)
B13: 3 | C13: BILL NO 3 | D13: PROVISIONAL SUM | E13: =F13 -> 200000 | F13: 200000 | G13: 0 | H13: 0 | I13: 200000 | J13: =I13-H13 -> 200000 | K13: 0 | L13: 0 | M13: =K13-J13 -> -200000 | O13: =F13-K13 -> 200000 | P13: =J13/F13*100 -> 100 | Q13: =K13/$K$33 -> 0 | T13: Bill No 3. (PROVISIONAL SUM)
B15: 4 | C15: BILL NO 4 | D15: NEW HOUSING UNIT (20 UNITS) | E15: =F17+F19 -> 1965370.9 | R15: =SUM(Q17,Q19) -> 0.45396819
D17: SUBSTRUCTURE WORKS | F17: =SUMMARY!D11 -> 947257 | G17: =F17 -> 947257 | H17: 0 | I17: =F17-L17 -> 311793.25 | J17: =I17-H17 -> 311793.25 | K17: =F17-J17 -> 635463.75 | L17: 635463.75 | M17: =J17-K17 -> -323670.49 | O17: =SUMMARY!G11 -> 291914.71 | P17: =J17/F17*100 -> 32.915381 | Q17: =K17/$K$33 -> 0.18852752 | S17: 12.1 | T17: 20 NEW ADD QTY
D19: SUPERSTRUCTURE WORKS | F19: =SUMMARY!D21 -> 1018113.9 | G19: =F19 -> 1018113.9 | H19: 0 | I19: =SUMMARY!G21 -> 123401.5 | J19: =I19-H19 -> 123401.5 | K19: =F19-J19 -> 894712.44 | L19: 384919.88 | M19: =K19-J19 -> 771310.94 | N19: =SUMMARY!H21 -> 23100 | O19: =SUMMARY!G21 -> 123401.5 | P19: =J19/F19*100 -> 12.120598 | Q19: =K19/$K$33 -> 0.26544067 | S19: 12.2 | T19: GRAND SUM. ADD. (Bill No. 4 & 7)
B21: 5 | C21: BILL NO 4 | D21: EXTERNAL WORKS AND EXTERNAL SERVICES | E21: =F21 -> 28455 | F21: =SUMMARY!D27 -> 28455 | G21: =F21 -> 28455 | I21: =SUMMARY!G27 -> 2100 | J21: =I21-H21 -> 2100 | K21: =F21-J21 -> 26355 | L21: 0 | M21: =K21 -> 26355 | O21: =SUMMARY!G27 -> 2100 | P21: =J21/F21*100 -> 7.3800738 | Q21: =K21/$K$33 -> 0.0078189242 | R21: =Q21 -> 0.0078189242 | T21: BIll No 4 (20 NHI EXXTERNAL WORK)
B23: 6 | C23: BILL NO 5 | D23: MAINTENANCE WORKS FOR THE EXISTING HOUSING UNITS (29 NO) | E23: =F23 -> 1436308.6 | F23: =SUMMARY!D13 -> 1436308.6 | G23: =F23 -> 1436308.6 | H23: =SUMMARY!H13 -> 11890 | I23: ='SUMMARY OF BILL NO. (4 - 7)'!N75 -> 9991.805 | J23: =I23-H23 -> -1898.195 | K23: =F23-J23 -> 1438206.8 | L23: 1386819.3 | M23: =K23-J23 -> 1440105 | N23: =SUMMARY!H13 -> 11890 | O23: =SUMMARY!G13 -> 9991.805 | P23: =J23/F23*100 -> -0.13215788 | Q23: =K23/$K$33 -> 0.42668298 | R23: =Q23 -> 0.42668298 | S23: 12.2 | T23: ADD. WORK (29 - MHU)
B25: 7 | C25: BILL NO 6 | D25: PROTECTION AND STORM WATER DRAINAGE | E25: =F25 -> 265674.67 | F25: =SUMMARY!D16 -> 265674.67 | G25: =F25 -> 265674.67 | H25: 0 | I25: ='Copy of BILL NO 6 (STORM WATER)'!J52 -> 186375.12 | J25: =I25-H25 -> 186375.12 | K25: =F25-J25 -> 79299.558 | L25: 6120.135 | M25: =J25-K25 -> 107075.56 | O25: =F25-K25 -> 186375.12 | P25: =J25/F25*100 -> 70.151631 | Q25: =K25/$K$33 -> 0.02352636 | R25: =Q25 -> 0.02352636 | T25: ADD. WORK ON CHANNEL
B27: 8 | C27: BILL NO 7 | D27: 3 NUMBER HOUSING UNITS | E27: =F29+F31 -> 239991.02 | R27: =SUM(Q29,Q31) -> 0.057511079
D29: SUBSTRUCTURE WORKS | F29: =SUMMARY!D18 -> 36105 | G29: =F29 -> 36105 | H29: 0 | I29: =F29-L29 -> 10515.096 | J29: =I29-H29 -> 10515.096 | K29: =F29-J29 -> 25589.904 | L29: 25589.904 | M29: =K29-J29 -> 15074.808 | O29: =SUMMARY!G18 -> 10515.156 | P29: =J29/F29*100 -> 29.123656 | Q29: =K29/$K$33 -> 0.0075919377 | S29: 12.1 | T29: 20 NHU ADD. QTY/ Bill No 7. (3 NHU)
D31: SUPERSTRUCTURE WORK | F31: =SUMMARY!D23 -> 203886.02 | G31: =F31 -> 203886.02 | H31: 0 | I31: ='BILL NO 7. (3 NHU)'!M193 -> 35625.156 | J31: =I31-H31 -> 35625.156 | K31: =F31-J31 -> 168260.87 | L31: 28323 | M31: =K31-J31 -> 132635.71 | N31: =SUMMARY!H23 -> 1111.44 | O31: =SUMMARY!G23 -> 25110 | P31: =J31/F31*100 -> 17.473074 | Q31: =K31/$K$33 -> 0.049919142 | S31: 12.2 | T31: SUM. OF ADD. WORKS (Bill No 4 & 7)
B33: Total Contract Value | E33: =SUM(E9:E32) -> 4451632.7 | F33: =SUM(F9:F31) -> 4451632.7 | G33: =SUM(G9+G11+G17+G19+G21+G23+G25+G29+G31+G13) -> 4251632.7 | H33: =SUM(H9+H11+H17+H19+H23+H25+H29+H31) -> 11890 | I33: =SUM(I9+I11+I17+I19+I21+I23+I25+I29+I31+I13) -> 1092854.4 | J33: =SUM(J9+J11+J17+J19+J21+J23+J25+J29+J31+J13) -> 1080964.4 | K33: =SUM(K9+K11+K17+K19+K21+K23+K25+K29+K31+K15+K13) -> 3370668.3 | L33: =SUM(L9+L11+L17+L19+L21+L23+L25+L29+L31+L13) -> 2542491.5 | M33: =F33-K33 -> 1080964.4 | N33: =SUM(N9:N31) -> 36101.44 | O33: =SUM(O9:O32) -> 1062470.8
H36: =I33-H33 -> 1080964.4 | K36: =F33-K33 -> 1080964.4 | O36: =SUM(O33:O35) -> 1062470.8
M37: =I33+J33 -> 2173818.9
F38: CONTRACT PRICE | K38: CLAIMABLE | O38: ADD/OMISSION IMPACT | Q38: =328588.41+7678.88 -> 336267.29 | S38: =55*355 -> 19525
Q39: =Q38-220352 -> 115915.29 | S39: =S38*32 -> 624800 | T39: =S39+K33 -> 3995468.3
D40: PERCENTAGE | F40: AMOUNT | K40: PERCENTAGE | M40: =J33+K36 -> 2161928.9 | O40: =#REF!-F36 -> #REF!
C42: Addition/Omission and Change Order Impact | D42: CONTRACT TOTAL VALUE | F42: =F33 -> 4451632.7 | K42: =F42/F42 -> 1 | M42: =H37-J37 -> 0 | T42: =F33-T39 -> 456164.43
D43: CLAIMABLE TOTAL AMOUNT | F43: =K33 -> 3370668.3 | K43: =F43/F42 -> 0.75717574
D44: ADDITION OMMISSION IMPACT | F44: =O36 -> 1062470.8 | K44: =F44/F42 -> 0.23866991
D45: ADDITIONAL WORK BILL NO. 5 | F45: =SUMMARY!H23 -> 1111.44 | K45: =(F45+F46)/F42 -> 0.049748812 | O45: =F45+F46 -> 221463.44
D46: CHANGE ORDER -2 | F46: 220352
D47: NET FINANCIAL IMPACT | F47: =F42*K47 -> 3592131.8 | K47: =K43+K45 -> 0.80692455
C48: Progress Impact | D48: OVERALL FINANCIAL IMPACT | K48: =K42-K47 -> 0.19307545
D49: CLAIMED TO DATE AGAINST CONTRACT | F49: 2193954.4 | K49: =2193954.35/F42 -> 0.49284262 | O49: =(K49+K50)/2 -> 0.57186928
D50: CLAIMED AGAINST CLAIMABLE VALUE | F50: 2193954.4 | K50: =F50/F43 -> 0.65089595
D51: CLAIMABLE AMOUNT - BILL 11 (13-04-26) | F51: 110000 | K51: =F51/F42 -> 0.024710035
K52: =K50-K49+K51 -> 0.18276336 | O52: =69.5%-O49 -> 0.12313072
D53: Progres Against Contract Vs Revised Value | K53: Planned VS Actual Cost | O53: Planned Vs Actual Progress
K58: =J33+K33 -> 4451632.7
J59: =J33/32 -> 33780.138
J60: =J59/55 -> 614.18433 | K60: =K58-F33 -> 0

Sheet 2ND GRAND SUMMARY (All Addition
B2: CONSTRUCTION, COMPLETION AND MAINTENANCE OF PROPOSED (20NOS) HOUSING UNITS AND MAINTENANCE WORKS FOR THE EXISTING (32) HOUSES FOR THE MINISTRY
B3: GRAND SUMMARY
B4: Priced Bill Of Quantities
B5: Transfer the Contract Summary of Contract Value to the Form of Tender
B7: S/N | C7: BILL NO | D7: DESCRIPTION | E7: BOQ AMOUNT | F7: BOQ AMOUNT | G7: REVISED VALUE AFTER V.O 1 | H7: Addition | I7: Omission | J7: Savings Excluding V.O 1 | K7: EXPECTED REVISED BOQ VALUE AFTER A/O | L7: AMOUNT CLAIMED AS PER BILL NO. 12 | N7: ADDITION AMOUNT/VARIATION | O7: SAVING AMOUNT | P7: % | S7: CLAUSES | T7: Appendix
B9: 1 | C9: BILL NO 1 | D9: PRELIMINARIES | E9: =F9 -> 227580 | F9: =SUMMARY!D4 -> 227580 | G9: =F9 -> 227580 | H9: 0 | I9: 124800 | J9: =I9-H9 -> 124800 | K9: =F9-J9 -> 102780 | L9: 75255.52 | M9: =K9-F9 -> -124800 | O9: =F9-K9 -> 124800 | P9: =J9/F9*100 -> 54.837859 | Q9: =K9/$K$33 -> 0.02758638 | R9: =Q9 -> 0.02758638 | T9: Bill No 1. (PRELIMINARIES)
B11: 2 | C11: BILL NO 2 | D11: DAY WORKS | E11: =F11 -> 88252.5 | F11: =SUMMARY!D6 -> 88252.5 | G11: =F11 -> 88252.5 | H11: 0 | I11: 88252.5 | J11: =I11-H11 -> 88252.5 | K11: =F11-J11 -> 0 | L11: 0 | M11: =J11-K11 -> 88252.5 | O11: =SUMMARY!G6 -> 88262.5 | P11: =J11/F11*100 -> 100 | Q11: =K11/$K$33 -> 0 | R11: =Q11 -> 0 | T11: Bill No 2. (DAY WORK)
B13: 3 | C13: BILL NO 3 | D13: PROVISIONAL SUM | E13: =F13 -> 200000 | F13: 200000 | G13: 0 | H13: 0 | I13: 200000 | J13: =I13-H13 -> 200000 | K13: 0 | L13: 0 | M13: =K13-J13 -> -200000 | O13: =F13-K13 -> 200000 | P13: =J13/F13*100 -> 100 | Q13: =K13/$K$33 -> 0 | T13: Bill No 3. (PROVISIONAL SUM)
B15: 4 | C15: BILL NO 4 | D15: NEW HOUSING UNIT (20 UNITS) | E15: =F17+F19 -> 1965370.9 | R15: =SUM(Q17,Q19) -> 0.4526665
D17: SUBSTRUCTURE WORKS | F17: =SUMMARY!D11 -> 947257 | G17: =F17 -> 947257 | H17: ='20 NHU ADD. QTY'!H33 -> 41896.539 | I17: =F17-L17 -> 311793.25 | J17: =I17-H17 -> 269896.72 | K17: =F17-J17 -> 677360.28 | L17: 635463.75 | M17: =J17-K17 -> -407463.57 | O17: =SUMMARY!G11 -> 291914.71 | P17: =J17/F17*100 -> 28.492449 | Q17: =K17/$K$33 -> 0.181805 | S17: 12.1 | T17: 20 NEW ADD QTY
D19: SUPERSTRUCTURE WORKS | F19: =SUMMARY!D21 -> 1018113.9 | G19: =F19 -> 1018113.9 | H19: ='SUM. OF ADD. WORKS (BILL NO. 4 '!F135 -> 114450.24 | I19: =SUMMARY!G21 -> 123401.5 | J19: =I19-H19 -> 8951.2562 | K19: =F19-J19 -> 1009162.7 | L19: 384919.88 | M19: =K19-J19 -> 1000211.4 | N19: =SUMMARY!H21 -> 23100 | O19: =SUMMARY!G21 -> 123401.5 | P19: =J19/F19*100 -> 0.87919984 | Q19: =K19/$K$33 -> 0.2708615 | S19: 12.2 | T19: GRAND SUM. ADD. (Bill No. 4 & 7) | Y19: =K19-F19 -> -8951.2562
B21: 5 | C21: BILL NO 4 | D21: EXTERNAL WORKS AND EXTERNAL SERVICES | E21: =F21 -> 28455 | F21: =SUMMARY!D27 -> 28455 | G21: =F21 -> 28455 | I21: =SUMMARY!G27 -> 2100 | J21: =I21-H21 -> 2100 | K21: =F21-J21 -> 26355 | L21: 0 | M21: =K21 -> 26355 | O21: =SUMMARY!G27 -> 2100 | P21: =J21/F21*100 -> 7.3800738 | Q21: =K21/$K$33 -> 0.0070737404 | R21: =Q21 -> 0.0070737404 | T21: BIll No 4 (20 NHI EXXTERNAL WORK)
B23: 6 | C23: BILL NO 5 | D23: MAINTENANCE WORKS FOR THE EXISTING HOUSING UNITS (29 NO) | E23: =F23 -> 1436308.6 | F23: =SUMMARY!D13 -> 1436308.6 | G23: =F23 -> 1436308.6 | H23: =SUMMARY!H13 -> 11890 | I23: ='SUMMARY OF BILL NO. (4 - 7)'!N75 -> 9991.805 | J23: =I23-H23 -> -1898.195 | K23: =F23-J23 -> 1438206.8 | L23: 1386819.3 | M23: =K23-J23 -> 1440105 | N23: =SUMMARY!H13 -> 11890 | O23: =SUMMARY!G13 -> 9991.805 | P23: =J23/F23*100 -> -0.13215788 | Q23: =K23/$K$33 -> 0.38601789 | R23: =Q23 -> 0.38601789 | S23: 12.2 | T23: ADD. WORK (29 - MHU)
B25: 7 | C25: BILL NO 6 | D25: PROTECTION AND STORM WATER DRAINAGE | E25: =F25 -> 265674.67 | F25: =SUMMARY!D16 -> 265674.67 | G25: =F25 -> 265674.67 | H25: 0 | I25: ='BILL NO 6 (STORM WATER)'!I36 -> 0 | J25: =I25-H25 -> 0 | K25: =F25-J25 -> 265674.67 | L25: 6120.135 | M25: =J25-K25 -> -265674.67 | O25: =F25-K25 -> 0 | P25: =J25/F25*100 -> 0 | Q25: =K25/$K$33 -> 0.071307671 | R25: =Q25 -> 0.071307671 | T25: ADD. WORK ON CHANNEL
B27: 8 | C27: BILL NO 7 | D27: 3 NUMBER HOUSING UNITS | E27: =F29+F31 -> 239991.02 | R27: =SUM(Q29,Q31) -> 0.055347815
D29: SUBSTRUCTURE WORKS | F29: =SUMMARY!D18 -> 36105 | G29: =F29 -> 36105 | H29: ='20 NHU ADD. QTY'!H62 -> 11250 | I29: =F29-L29 -> 10515.096 | J29: =I29-H29 -> -734.904 | K29: =F29-J29 -> 36839.904 | L29: 25589.904 | M29: =K29-J29 -> 37574.808 | O29: =SUMMARY!G18 -> 10515.156 | P29: =J29/F29*100 -> -2.0354632 | Q29: =K29/$K$33 -> 0.0098879119 | S29: 12.1 | T29: 20 NHU ADD. QTY/ Bill No 7. (3 NHU)
D31: SUPERSTRUCTURE WORK | F31: =SUMMARY!D23 -> 203886.02 | G31: =F31 -> 203886.02 | H31: ='SUM. OF ADD. WORKS (BILL NO. 4 '!G17 -> 1111.44 | I31: ='BILL NO 7. (3 NHU)'!M193 -> 35625.156 | J31: =I31-H31 -> 34513.716 | K31: =F31-J31 -> 169372.31 | L31: 28323 | M31: =K31-J31 -> 134858.59 | N31: =SUMMARY!H23 -> 1111.44 | O31: =SUMMARY!G23 -> 25110 | P31: =J31/F31*100 -> 16.927946 | Q31: =K31/$K$33 -> 0.045459903 | S31: 12.2 | T31: SUM. OF ADD. WORKS (Bill No 4 & 7)
B33: Total Contract Value | E33: =SUM(E9:E32) -> 4451632.7 | F33: =SUM(F9:F31) -> 4451632.7 | G33: =SUM(G9+G11+G17+G19+G21+G23+G25+G29+G31+G13) -> 4251632.7 | H33: =SUM(H9+H11+H17+H19+H23+H25+H29+H31) -> 180598.22 | I33: =SUM(I9+I11+I17+I19+I21+I23+I25+I29+I31+I13) -> 906479.31 | J33: =SUM(J9+J11+J17+J19+J21+J23+J25+J29+J31+J13) -> 725881.09 | K33: =SUM(K9+K11+K17+K19+K21+K23+K25+K29+K31+K15+K13) -> 3725751.7 | L33: =SUM(L9+L11+L17+L19+L21+L23+L25+L29+L31+L13) -> 2542491.5 | M33: =F33-K33 -> 725881.09 | N33: =SUM(N9:N31) -> 36101.44 | O33: =SUM(O9:O32) -> 876095.67
H36: =I33-H33 -> 725881.09 | K36: =F33-K33 -> 725881.09 | O36: =SUM(O33:O35) -> 876095.67
M37: =I33+J33 -> 1632360.4
F38: CONTRACT PRICE | K38: CLAIMABLE | O38: ADD/OMISSION IMPACT | Q38: =328588.41+7678.88 -> 336267.29 | S38: =55*355 -> 19525
Q39: =Q38-220352 -> 115915.29 | S39: =S38*32 -> 624800 | T39: =S39+K33 -> 4350551.7
D40: PERCENTAGE | F40: AMOUNT | K40: PERCENTAGE | M40: =J33+K36 -> 1451762.2 | O40: =#REF!-F36 -> #REF!
C42: Addition/Omission and Change Order Impact | D42: CONTRACT TOTAL VALUE | F42: =F33 -> 4451632.7 | K42: =F42/F42 -> 1 | M42: =H37-J37 -> 0 | T42: =F33-T39 -> 101081.09
D43: CLAIMABLE TOTAL AMOUNT | F43: =K33 -> 3725751.7 | K43: =F43/F42 -> 0.83694048
D44: ADDITION OMMISSION IMPACT | F44: =O36 -> 876095.67 | K44: =F44/F42 -> 0.19680322
D45: ADDITIONAL WORK BILL NO. 5 | F45: =SUMMARY!H23 -> 1111.44 | K45: =(F45+F46)/F42 -> 0.049748812 | O45: =F45+F46 -> 221463.44
D46: CHANGE ORDER -2 | F46: 220352
D47: NET FINANCIAL IMPACT | F47: =F42*K47 -> 3947215.1 | K47: =K43+K45 -> 0.88668929
C48: Progress Impact | D48: OVERALL FINANCIAL IMPACT | K48: =K42-K47 -> 0.11331071
D49: CLAIMED TO DATE AGAINST CONTRACT | F49: 2193954.4 | K49: =2193954.35/F42 -> 0.49284262 | O49: =(K49+K50)/2 -> 0.54085241
D50: CLAIMED AGAINST CLAIMABLE VALUE | F50: 2193954.4 | K50: =F50/F43 -> 0.58886221
D51: CLAIMABLE AMOUNT - BILL 11 (13-04-26) | F51: 110000 | K51: =F51/F42 -> 0.024710035
K52: =K50-K49+K51 -> 0.12072962 | O52: =69.5%-O49 -> 0.15414759
D53: Progres Against Contract Vs Revised Value | K53: Planned VS Actual Cost | O53: Planned Vs Actual Progress
K58: =J33+K33 -> 4451632.7
J59: =J33/32 -> 22683.784
J60: =J59/55 -> 412.43244 | K60: =K58-F33 -> 0

Sheet 3RD GRAND SUMMARY (Consultant S
B2: CONSTRUCTION, COMPLETION AND MAINTENANCE OF PROPOSED (20NOS) HOUSING UNITS AND MAINTENANCE WORKS FOR THE EXISTING (32) HOUSES FOR THE MINISTRY
B3: GRAND SUMMARY
B4: Priced Bill Of Quantities
B5: Transfer the Contract Summary of Contract Value to the Form of Tender
B7: S/N | C7: BILL NO | D7: DESCRIPTION | E7: BOQ AMOUNT | F7: BOQ AMOUNT | G7: REVISED VALUE AFTER V.O 1 | H7: Addition | I7: Omission | J7: Savings Excluding V.O 1 | K7: EXPECTED REVISED BOQ VALUE AFTER A/O | L7: AMOUNT CLAIMED AS PER BILL NO. 12 | N7: ADDITION AMOUNT/VARIATION | O7: SAVING AMOUNT | P7: % | S7: CLAUSES | T7: Appendix
B9: 1 | C9: BILL NO 1 | D9: PRELIMINARIES | E9: =F9 -> 227580 | F9: =SUMMARY!D4 -> 227580 | G9: =F9 -> 227580 | H9: 0 | I9: 124800 | J9: =I9-H9 -> 124800 | K9: =F9-J9 -> 102780 | L9: 75255.52 | M9: =K9-F9 -> -124800 | O9: =F9-K9 -> 124800 | P9: =J9/F9*100 -> 54.837859 | Q9: =K9/$K$33 -> 0.028894784 | R9: =Q9 -> 0.028894784 | T9: Bill No 1. (PRELIMINARIES)
B11: 2 | C11: BILL NO 2 | D11: DAY WORKS | E11: =F11 -> 88252.5 | F11: =SUMMARY!D6 -> 88252.5 | G11: =F11 -> 88252.5 | H11: 0 | I11: 88252.5 | J11: =I11-H11 -> 88252.5 | K11: =F11-J11 -> 0 | L11: 0 | M11: =J11-K11 -> 88252.5 | O11: =SUMMARY!G6 -> 88262.5 | P11: =J11/F11*100 -> 100 | Q11: =K11/$K$33 -> 0 | R11: =Q11 -> 0 | T11: Bill No 2. (DAY WORK)
B13: 3 | C13: BILL NO 3 | D13: PROVISIONAL SUM | E13: =F13 -> 200000 | F13: 200000 | G13: 0 | H13: 0 | I13: 200000 | J13: =I13-H13 -> 200000 | K13: 0 | L13: 0 | M13: =K13-J13 -> -200000 | O13: =F13-K13 -> 200000 | P13: =J13/F13*100 -> 100 | Q13: =K13/$K$33 -> 0 | T13: Bill No 3. (PROVISIONAL SUM)
B15: 4 | C15: BILL NO 4 | D15: NEW HOUSING UNIT (20 UNITS) | E15: =F17+F19 -> 1965370.9 | R15: =SUM(Q17,Q19) -> 0.43018204
D17: SUBSTRUCTURE WORKS | F17: =SUMMARY!D11 -> 947257 | G17: =F17 -> 947257 | H17: 0 | I17: =F17-L17 -> 311793.25 | J17: =I17-H17 -> 311793.25 | K17: =F17-J17 -> 635463.75 | L17: 635463.75 | M17: =J17-K17 -> -323670.49 | O17: =SUMMARY!G11 -> 291914.71 | P17: =J17/F17*100 -> 32.915381 | Q17: =K17/$K$33 -> 0.17864942 | S17: 12.1 | T17: 20 NEW ADD QTY
D19: SUPERSTRUCTURE WORKS | F19: =SUMMARY!D21 -> 1018113.9 | G19: =F19 -> 1018113.9 | H19: 0 | I19: =SUMMARY!G21 -> 123401.5 | J19: =I19-H19 -> 123401.5 | K19: =F19-J19 -> 894712.44 | L19: 384919.88 | M19: =K19-J19 -> 771310.94 | N19: =SUMMARY!H21 -> 23100 | O19: =SUMMARY!G21 -> 123401.5 | P19: =J19/F19*100 -> 12.120598 | Q19: =K19/$K$33 -> 0.25153262 | S19: 12.2 | T19: GRAND SUM. ADD. (Bill No. 4 & 7)
B21: 5 | C21: BILL NO 4 | D21: EXTERNAL WORKS AND EXTERNAL SERVICES | E21: =F21 -> 28455 | F21: =SUMMARY!D27 -> 28455 | G21: =F21 -> 28455 | I21: =SUMMARY!G27 -> 2100 | J21: =I21-H21 -> 2100 | K21: =F21-J21 -> 26355 | L21: 0 | M21: =K21 -> 26355 | O21: =SUMMARY!G27 -> 2100 | P21: =J21/F21*100 -> 7.3800738 | Q21: =K21/$K$33 -> 0.0074092432 | R21: =Q21 -> 0.0074092432 | T21: BIll No 4 (20 NHI EXXTERNAL WORK)
B23: 6 | C23: BILL NO 5 | D23: MAINTENANCE WORKS FOR THE EXISTING HOUSING UNITS (29 NO) | E23: =F23 -> 1436308.6 | F23: =SUMMARY!D13 -> 1436308.6 | G23: =F23 -> 1436308.6 | H23: =SUMMARY!H13 -> 11890 | I23: ='SUMMARY OF BILL NO. (4 - 7)'!N75 -> 9991.805 | J23: =I23-H23 -> -1898.195 | K23: =F23-J23 -> 1438206.8 | L23: 1386819.3 | M23: =K23-J23 -> 1440105 | N23: =SUMMARY!H13 -> 11890 | O23: =SUMMARY!G13 -> 9991.805 | P23: =J23/F23*100 -> -0.13215788 | Q23: =K23/$K$33 -> 0.40432647 | R23: =Q23 -> 0.40432647 | S23: 12.2 | T23: ADD. WORK (29 - MHU)
B25: 7 | C25: BILL NO 6 | D25: PROTECTION AND STORM WATER DRAINAGE | E25: =F25 -> 265674.67 | F25: =SUMMARY!D16 -> 265674.67 | G25: =F25 -> 265674.67 | H25: 0 | I25: ='BILL NO 6 (STORM WATER)'!I36 -> 0 | J25: =I25-H25 -> 0 | K25: =F25-J25 -> 265674.67 | L25: 6120.135 | M25: =J25-K25 -> -265674.67 | O25: =F25-K25 -> 0 | P25: =J25/F25*100 -> 0 | Q25: =K25/$K$33 -> 0.074689747 | R25: =Q25 -> 0.074689747 | T25: ADD. WORK ON CHANNEL
B27: 8 | C27: BILL NO 7 | D27: 3 NUMBER HOUSING UNITS | E27: =F29+F31 -> 239991.02 | R27: =SUM(Q29,Q31) -> 0.054497724
D29: SUBSTRUCTURE WORKS | F29: =SUMMARY!D18 -> 36105 | G29: =F29 -> 36105 | H29: 0 | I29: =F29-L29 -> 10515.096 | J29: =I29-H29 -> 10515.096 | K29: =F29-J29 -> 25589.904 | L29: 25589.904 | M29: =K29-J29 -> 15074.808 | O29: =SUMMARY!G18 -> 10515.156 | P29: =J29/F29*100 -> 29.123656 | Q29: =K29/$K$33 -> 0.00719415 | S29: 12.1 | T29: 20 NHU ADD. QTY/ Bill No 7. (3 NHU)
D31: SUPERSTRUCTURE WORK | F31: =SUMMARY!D23 -> 203886.02 | G31: =F31 -> 203886.02 | H31: 0 | I31: ='BILL NO 7. (3 NHU)'!M193 -> 35625.156 | J31: =I31-H31 -> 35625.156 | K31: =F31-J31 -> 168260.87 | L31: 28323 | M31: =K31-J31 -> 132635.71 | N31: =SUMMARY!H23 -> 1111.44 | O31: =SUMMARY!G23 -> 25110 | P31: =J31/F31*100 -> 17.473074 | Q31: =K31/$K$33 -> 0.047303574 | S31: 12.2 | T31: SUM. OF ADD. WORKS (Bill No 4 & 7)
B33: Total Contract Value | E33: =SUM(E9:E32) -> 4451632.7 | F33: =SUM(F9:F31) -> 4451632.7 | G33: =SUM(G9+G11+G17+G19+G21+G23+G25+G29+G31+G13) -> 4251632.7 | H33: =SUM(H9+H11+H17+H19+H23+H25+H29+H31) -> 11890 | I33: =SUM(I9+I11+I17+I19+I21+I23+I25+I29+I31+I13) -> 906479.31 | J33: =SUM(J9+J11+J17+J19+J21+J23+J25+J29+J31+J13) -> 894589.31 | K33: =SUM(K9+K11+K17+K19+K21+K23+K25+K29+K31+K15+K13) -> 3557043.4 | L33: =SUM(L9+L11+L17+L19+L21+L23+L25+L29+L31+L13) -> 2542491.5 | M33: =F33-K33 -> 894589.31 | N33: =SUM(N9:N31) -> 36101.44 | O33: =SUM(O9:O32) -> 876095.67
H36: =I33-H33 -> 894589.31 | K36: =F33-K33 -> 894589.31 | O36: =SUM(O33:O35) -> 876095.67
M37: =I33+J33 -> 1801068.6
F38: CONTRACT PRICE | K38: CLAIMABLE | O38: ADD/OMISSION IMPACT | Q38: =328588.41+7678.88 -> 336267.29 | S38: =55*355 -> 19525
Q39: =Q38-220352 -> 115915.29 | S39: =S38*32 -> 624800 | T39: =S39+K33 -> 4181843.4
D40: PERCENTAGE | F40: AMOUNT | K40: PERCENTAGE | M40: =J33+K36 -> 1789178.6 | O40: =#REF!-F36 -> #REF!
C42: Addition/Omission and Change Order Impact | D42: CONTRACT TOTAL VALUE | F42: =F33 -> 4451632.7 | K42: =F42/F42 -> 1 | M42: =H37-J37 -> 0 | T42: =F33-T39 -> 269789.31
D43: CLAIMABLE TOTAL AMOUNT | F43: =K33 -> 3557043.4 | K43: =F43/F42 -> 0.79904243
D44: ADDITION OMMISSION IMPACT | F44: =O36 -> 876095.67 | K44: =F44/F42 -> 0.19680322
D45: ADDITIONAL WORK BILL NO. 5 | F45: =SUMMARY!H23 -> 1111.44 | K45: =(F45+F46)/F42 -> 0.049748812 | O45: =F45+F46 -> 221463.44
D46: CHANGE ORDER -2 | F46: 220352
D47: NET FINANCIAL IMPACT | F47: =F42*K47 -> 3778506.9 | K47: =K43+K45 -> 0.84879124
C48: Progress Impact | D48: OVERALL FINANCIAL IMPACT | K48: =K42-K47 -> 0.15120876
D49: CLAIMED TO DATE AGAINST CONTRACT | F49: 2193954.4 | K49: =2193954.35/F42 -> 0.49284262 | O49: =(K49+K50)/2 -> 0.55481709
D50: CLAIMED AGAINST CLAIMABLE VALUE | F50: 2193954.4 | K50: =F50/F43 -> 0.61679155
D51: CLAIMABLE AMOUNT - BILL 11 (13-04-26) | F51: 110000 | K51: =F51/F42 -> 0.024710035
K52: =K50-K49+K51 -> 0.14865897 | O52: =69.5%-O49 -> 0.14018291
D53: Progres Against Contract Vs Revised Value | K53: Planned VS Actual Cost | O53: Planned Vs Actual Progress
K58: =J33+K33 -> 4451632.7
J59: =J33/32 -> 27955.916
J60: =J59/55 -> 508.28938 | K60: =K58-F33 -> 0

Sheet Sheet38
B2: S/N | C2: DESCRIPTION OF WORK | D2: UOM | E2: QTY | F2: RATE | G2: AMOUNT
B3: 1 | C3: MAINTENANCE EXTENSION | D3: SQM | E3: 1760 | F3: 447.71 | G3: =E3*F3 -> 787969.6
B5: 2 | C5: REVISED DOORS
C6: D1 - ALUM. DOOR | D6: NR | E6: 20 | F6: 1300 | G6: =E6*F6 -> 26000
C7: D2 - ALUM. DOOR | D7: NR | E7: 20 | F7: 400 | G7: =E7*F7 -> 8000
G10: =SUM(G3:G9) -> 821969.6

Sheet SUMMARY
B2: S/N | C2: DESCRIPTION | D2: BOQ AMOUNT | E2: REVISED AMOUNT (CLAIMABLE) | G2: OMISSION AMOUNT (SAVINGS) | H2: ADDITION AMOUNT | I2: ENQUIRY ON ITEM OF WORK (AMOUNT)
B4: BILL NO 1 | C4: PRELIMINARIES | D4: ='BILL NO 1. (PRELIMINARIES)'!I146 -> 227580 | E4: ='BILL NO 1. (PRELIMINARIES)'!J146 -> 102780 | G4: ='BILL NO 1. (PRELIMINARIES)'!L146 -> 124800 | I4: -------------
B6: BILL NO 2 | C6: DAY WORK | D6: ='BILL NO 2. (DAY WORK)'!H120 -> 88252.5 | E6: ='BILL NO 2. (DAY WORK)'!J120 -> 0 | G6: ='BILL NO 2. (DAY WORK)'!K120 -> 88262.5 | I6: -------------
B8: BILL NO 3 | C8: PROVISIONAL SUM | D8: ='BILL NO 3. (PROVISIONAL SUM)'!I11 -> 200000 | E8: 0 | G8: ='BILL NO 3. (PROVISIONAL SUM)'!K11 -> 200000 | I8: -------------
C10: SUBSTRUCTURE WORK
B11: BILL NO 4 | C11: 20 NEW HOUSING UNIT | D11: ='BILL NO4. (20 NHU)'!I34 -> 947257 | E11: ='BILL NO4. (20 NHU)'!K34 -> 656066.04 | G11: ='BILL NO4. (20 NHU)'!M34 -> 291914.71 | I11: -------------
B13: BILL NO 5 | C13: MAINTENANCE HOUSING UNIT - 29 UNIT | D13: ='BILL NO 5. (MAINTENANCE HOUSING'!I116 -> 1436308.6 | E13: ='BILL NO 5. (MAINTENANCE HOUSING'!K116 -> 1426316.8 | G13: ='SUMMARY OF BILL NO. (4 - 7)'!N75 -> 9991.805 | H13: ='APPENDIX - B'!G24 -> 11890 | I13: -------------
B16: BILL NO 6 | C16: PROTECTION AND STORM WATER DRAINAGE | D16: ='BILL NO 6 (STORM WATER)'!I35 -> 265674.67 | G16: ='Copy of BILL NO 6 (STORM WATER)'!K51 -> 265674.67 | I16: -------------
B18: BILL NO 7 | C18: 3 NEW HOUSING UNIT | D18: ='BILL NO 7. (3 NHU)'!I33*3 -> 36105 | E18: ='BILL NO 7. (3 NHU)'!K33*3 -> 25589.844 | G18: ='BILL NO 7. (3 NHU)'!M33*3 -> 10515.156 | I18: -------------
C20: SUPERSTRUCTURE WORK
B21: BILL NO 4 | C21: 20 NEW HOUSING UNIT | D21: ='BILL NO4. (20 NHU)'!I371-D11 -> 1018113.9 | E21: ='BILL NO4. (20 NHU)'!K371-E11 -> 894712.44 | G21: ='BILL NO4. (20 NHU)'!M371-G11 -> 123401.5 | H21: ='BILL NO4. (20 NHU)'!O371 -> 23100
B23: BILL NO 7 | C23: 3 NEW HOUSING UNIT | D23: =SUM('BILL NO 7. (3 NHU)'!I194+'BILL NO 7. (3 NHU)'!I115+'BILL NO 7. (3 NHU)'!I52+'BILL NO 7. (3 NHU)'!I46+'BILL NO 7. (3 NHU)'!I41+'BILL NO 7. (3 NHU)'!I36)*3+0.025 -> 203886.02 | E23: =SUM('BILL NO 7. (3 NHU)'!K194+'BILL NO 7. (3 NHU)'!K115+'BILL NO 7. (3 NHU)'!K52+'BILL NO 7. (3 NHU)'!K46+'BILL NO 7. (3 NHU)'!K41+'BILL NO 7. (3 NHU)'!K36)*3 -> 181521 | G23: ='BILL NO 7. (3 NHU)'!M193-G18 -> 25110 | H23: ='SUM. OF ADD. WORKS (BILL NO. 4 '!G17 -> 1111.44 | I23: -------------
B27: BILL NO 4 | C27: EXTERNAL WORK (20 NEW HOUSING UNIT) | D27: ='BILL NO 4 (20 NHU EXTERNAL WORK'!I15 -> 28455 | E27: ='BILL NO 4 (20 NHU EXTERNAL WORK'!K15 -> 26355 | G27: ='BILL NO 4 (20 NHU EXTERNAL WORK'!M14 -> 2100 | I27: -------------
D29: =SUM(D4:D28) -> 4451632.7 | E29: =SUM(E4:E28)+I21 -> 3313341.1 | F29: =D29-E29 -> 1138291.6 | G29: =SUM(G4:G28) -> 1141770.3

Sheet SUMMARY OF BILL NO. (4 - 7)
B2: BILL NO 4 (20 NEW HOUSING UNIT)
B3: #REF! | C3: #REF! | D3: #REF! | E3: #REF! | F3: #REF! | G3: #REF! | H3: #REF! | I3: #REF! | J3: #REF! | K3: #REF! | L3: #REF! | M3: ADDITION AMOUNT | N3: ='[1]BILL NO 4 (20'!M2 -> #REF!
B6: #REF! | C6: #REF! | D6: #REF! | E6: #REF! | F6: #REF! | G6: #REF! | H6: #REF! | I6: #REF! | J6: #REF! | K6: #REF! | L6: #REF! | N6: #REF!
B7: #REF! | C7: #REF! | D7: #REF! | E7: #REF! | F7: #REF! | G7: #REF! | H7: #REF! | I7: #REF! | J7: #REF! | K7: #REF! | L7: #REF! | N7: #REF!
B8: #REF! | C8: #REF! | D8: #REF! | E8: #REF! | F8: #REF! | G8: #REF! | H8: #REF! | I8: #REF! | J8: #REF! | K8: #REF! | L8: #REF! | N8: #REF!
B9: #REF! | C9: #REF! | D9: #REF! | E9: #REF! | F9: #REF! | G9: #REF! | H9: #REF! | I9: #REF! | J9: #REF! | K9: #REF! | L9: #REF! | N9: #REF!
B10: #REF! | C10: #REF! | D10: #REF! | E10: #REF! | F10: #REF! | G10: #REF! | H10: #REF! | I10: #REF! | J10: #REF! | K10: #REF! | L10: #REF! | N10: #REF!
B11: #REF! | C11: #REF! | D11: #REF! | E11: #REF! | F11: #REF! | G11: #REF! | H11: #REF! | I11: #REF! | J11: #REF! | K11: #REF! | L11: #REF! | M11: =L11*G11 -> #VALUE! | N11: #REF!
B12: #REF! | C12: #REF! | D12: #REF! | E12: #REF! | F12: #REF! | G12: #REF! | H12: #REF! | I12: #REF! | J12: #REF! | K12: #REF! | L12: #REF! | N12: #REF!
B13: #REF! | C13: #REF! | D13: #REF! | E13: #REF! | F13: #REF! | G13: #REF! | H13: #REF! | I13: #REF! | J13: #REF! | K13: #REF! | L13: #REF! | N13: #REF!
B14: #REF! | C14: #REF! | D14: #REF! | E14: #REF! | F14: #REF! | G14: #REF! | H14: #REF! | I14: #REF! | J14: #REF! | K14: #REF! | L14: #REF! | N14: ='[1]BILL NO 4 (20'!M13 -> #REF!
B15: #REF! | C15: #REF! | D15: #REF! | E15: #REF! | F15: #REF! | G15: #REF! | H15: #REF! | I15: #REF! | J15: #REF! | K15: #REF! | L15: #REF! | N15: ='[1]BILL NO 4 (20'!M15 -> #REF!
B16: #REF! | C16: #REF! | D16: #REF! | E16: #REF! | F16: #REF! | G16: #REF! | H16: #REF! | I16: #REF! | J16: #REF! | K16: #REF! | L16: #REF! | N16: ='[1]BILL NO 4 (20'!M17 -> #REF!
B17: #REF! | C17: #REF! | D17: #REF! | E17: #REF! | F17: #REF! | G17: #REF! | H17: #REF! | I17: #REF! | J17: #REF! | K17: #REF! | L17: #REF! | N17: ='[1]BILL NO 4 (20'!M19 -> #REF!
B18: #REF! | C18: #REF! | D18: #REF! | E18: #REF! | F18: #REF! | G18: #REF! | H18: #REF! | I18: #REF! | J18: #REF! | K18: #REF! | L18: #REF! | N18: #REF!
B19: #REF! | C19: #REF! | D19: #REF! | E19: #REF! | F19: #REF! | G19: #REF! | H19: #REF! | I19: #REF! | J19: #REF! | K19: #REF! | L19: #REF! | N19: #REF!
B20: #REF! | C20: #REF! | D20: #REF! | E20: #REF! | F20: #REF! | G20: #REF! | H20: #REF! | I20: #REF! | J20: #REF! | K20: #REF! | L20: #REF! | N20: #REF!
B21: #REF! | C21: #REF! | D21: #REF! | E21: #REF! | F21: #REF! | G21: #REF! | H21: #REF! | I21: #REF! | J21: #REF! | K21: #REF! | L21: #REF! | N21: #REF!
B22: #REF! | C22: #REF! | D22: #REF! | E22: #REF! | F22: ='[1]BILL NO 4 (20'!F25 -> #REF! | G22: #REF! | H22: #REF! | I22: #REF! | J22: #REF! | K22: #REF! | L22: #REF! | N22: #REF!
B23: #REF! | C23: #REF! | D23: #REF! | E23: #REF! | F23: #REF! | G23: #REF! | H23: #REF! | I23: #REF! | J23: #REF! | K23: #REF! | L23: #REF! | N23: #REF!
C25: SUBSTRUCTURE WORKS | I25: =SUM(I6:I24) -> 0 | K25: =SUM(K6:K24) -> 0 | M25: =SUM(M6:M24) -> #VALUE! | N25: =SUM(N6:N24) -> #REF!
B26: #REF! | C26: #REF! | D26: #REF! | E26: #REF! | F26: #REF! | G26: #REF! | H26: #REF! | I26: #REF! | J26: #REF! | K26: #REF! | L26: #REF! | N26: #REF!
B27: #REF! | C27: #REF! | D27: #REF! | E27: #REF! | F27: #REF! | G27: #REF! | H27: #REF! | I27: #REF! | J27: #REF! | K27: #REF! | L27: #REF! | N27: #REF!
B28: #REF! | C28: #REF! | D28: #REF! | E28: #REF! | F28: #REF! | G28: #REF! | H28: #REF! | I28: #REF! | J28: #REF! | K28: #REF! | L28: #REF! | N28: #REF!
B29: #REF! | C29: #REF! | D29: #REF! | E29: #REF! | F29: #REF! | G29: #REF! | H29: #REF! | I29: #REF! | J29: #REF! | L29: ='[1]BILL NO 4 (20'!L211 -> #REF! | N29: =H29*G29 -> #VALUE!
B30: #REF! | C30: #REF! | D30: #REF! | E30: #REF! | F30: #REF! | G30: #REF! | H30: #REF! | I30: #REF! | J30: #REF! | K30: #REF! | L30: #REF! | N30: #REF!
B31: #REF! | C31: #REF! | D31: #REF! | E31: #REF! | F31: #REF! | G31: #REF! | H31: #REF! | I31: #REF! | J31: #REF! | K31: #REF! | L31: #REF! | N31: #REF!
B32: #REF! | C32: #REF! | D32: #REF! | E32: #REF! | F32: #REF! | G32: #REF! | H32: #REF! | I32: #REF! | J32: #REF! | K32: #REF! | L32: #REF! | N32: #REF!
B33: #REF! | C33: #REF! | D33: #REF! | E33: #REF! | F33: #REF! | G33: #REF! | H33: #REF! | I33: #REF! | J33: #REF! | K33: #REF! | L33: #REF! | N33: #REF!
B34: #REF! | C34: #REF! | D34: #REF! | E34: #REF! | F34: #REF! | G34: #REF! | H34: #REF! | I34: #REF! | J34: #REF! | L34: #REF! | N34: #REF!
B35: #REF! | C35: #REF! | D35: #REF! | E35: #REF! | F35: #REF! | G35: #REF! | H35: #REF! | I35: #REF! | J35: #REF! | L35: #REF! | N35: =G35*H35 -> #VALUE!
B36: #REF! | C36: #REF! | D36: #REF! | E36: #REF! | F36: #REF! | G36: #REF! | H36: #REF! | I36: #REF! | J36: #REF! | L36: #REF! | N36: =G36*H36 -> #VALUE!
B37: #REF! | C37: #REF! | D37: #REF! | E37: #REF! | F37: #REF! | G37: #REF! | H37: #REF! | I37: #REF! | J37: #REF! | N37: =H37*G37 -> #VALUE!
B38: #REF! | C38: #REF! | D38: #REF! | E38: #REF! | F38: #REF! | G38: #REF! | H38: #REF! | I38: #REF! | J38: #REF! | N38: =H38*G38 -> #VALUE!
B41: SUPERSTRUCTURE WORK | I41: =SUM(I26:I40) -> 0 | K41: =SUM(K26:K40) -> 0 | N41: =SUM(N26:N40) -> #VALUE!
B42: SUB - TOTAL
C43: SUBSTRUCTURE | I43: =I25 -> 0 | J43: =J25 -> 0 | K43: =K25 -> 0 | M43: =M25 -> #VALUE! | N43: =N25 -> #REF!
C44: SUPERSTRUCTURE | I44: =I41 -> 0 | K44: =K41 -> 0 | M44: =M41 -> 0 | N44: =N41 -> #VALUE!
B47: 20 NEW HOUSING UNITS | I47: =SUM(I43:I46) -> 0 | J47: =SUM(J43:J46) -> 0 | K47: =SUM(K43:K46) -> 0 | M47: =SUM(M43:M46) -> #VALUE! | N47: =SUM(N43:N46) -> #REF!
B51: BILLL NO 4 (EXTERNAL WORKS)
...

Sheet MAS 
B2: PROVISIONAL SUM
B3: ='BILL NO 3. (PROVISIONAL SUM)'!B3 -> Item Code | C3: ='BILL NO 3. (PROVISIONAL SUM)'!C3 -> Item Name | D3: ='BILL NO 3. (PROVISIONAL SUM)'!D3 -> Item Details | E3: ='BILL NO 3. (PROVISIONAL SUM)'!E3 -> Additional Information | F3: ='BILL NO 3. (PROVISIONAL SUM)'!F3 -> UOM | G3: ='BILL NO 3. (PROVISIONAL SUM)'!G3 -> Quantity | H3: ='BILL NO 3. (PROVISIONAL SUM)'!H3 -> Unit Price | I3: ='BILL NO 3. (PROVISIONAL SUM)'!I3 -> Total Price In Figure | J3: STATUS
B15: BILL NO. 4 (20 - NEW HOUSING UNITS)
B16: =B3 -> Item Code | C16: =C3 -> Item Name | D16: =D3 -> Item Details | E16: =E3 -> Additional Information | F16: =F3 -> UOM | G16: =G3 -> Quantity | H16: =H3 -> Unit Price | I16: =I3 -> Total Price In Figure
B17: ='BILL NO4. (20 NHU)'!B133 -> C91 | C17: ='BILL NO4. (20 NHU)'!C133 -> Superstructure Works Finishes | D17: ='BILL NO4. (20 NHU)'!D133 -> Allow for supply fabricate and installation of water point protection as per the specifications drawings and to approval of the Engineer. | E17: ='BILL NO4. (20 NHU)'!E133 -> Water point protection | F17: ='BILL NO4. (20 NHU)'!F133 -> No | G17: ='BILL NO4. (20 NHU)'!G133 -> 20 | H17: ='BILL NO4. (20 NHU)'!H133 -> 47.25 | I17: ='BILL NO4. (20 NHU)'!I133 -> 945 | J17: Pending | K17: Reason
B18: ='BILL NO4. (20 NHU)'!B134 -> C92 | C18: ='BILL NO4. (20 NHU)'!C134 -> Superstructure Works Finishes | D18: ='BILL NO4. (20 NHU)'!D134 -> Allow for supply fabricate and installation of Meter Panel protection as per the specifications drawings and to approval of the Engineer. | E18: ='BILL NO4. (20 NHU)'!E134 -> Meter Panel protection | F18: ='BILL NO4. (20 NHU)'!F134 -> No | G18: ='BILL NO4. (20 NHU)'!G134 -> 20 | H18: ='BILL NO4. (20 NHU)'!H134 -> 47.25 | I18: ='BILL NO4. (20 NHU)'!I134 -> 945 | J18: Pending | K18: Design Issue
B19: ='BILL NO4. (20 NHU)'!B211 -> F1 | C19: ='BILL NO4. (20 NHU)'!C211 -> Fire Fighting Installation | D19: ='BILL NO4. (20 NHU)'!D211 -> Fire Fighting Installation | E19: ='BILL NO4. (20 NHU)'!E211 -> Supply and install a complete fire fighting system to the approval of the Civil Defence Authorities and complete with association and fitting as shown in drawings or specified in accordance with BS 530 Part 1 1976 and Part 3 1985 and to approval of the Engineer. | F19: ='BILL NO4. (20 NHU)'!F211 -> Item | G19: ='BILL NO4. (20 NHU)'!G211 -> 1 | H19: ='BILL NO4. (20 NHU)'!H211 -> 0 | I19: ='BILL NO4. (20 NHU)'!I211 -> 0 | J19: Cancelled
B20: ='BILL NO4. (20 NHU)'!B212 -> F2 | C20: ='BILL NO4. (20 NHU)'!C212 -> Fire Fighting Installation | D20: ='BILL NO4. (20 NHU)'!D212 -> Fire hose reel | E20: ='BILL NO4. (20 NHU)'!E212 -> 1.5 mm thick Electro static powder coated painted stainless steel recessed type fire hose reel cabinet with 25 mm diameter hose reel and 45 meter long including 1 No. 9 litter foam type fire extinguisher and 1 No 5Kg carbon dioxide type fire extinguisher with civil defence final approval certificate. | F20: ='BILL NO4. (20 NHU)'!F212 -> No | G20: ='BILL NO4. (20 NHU)'!G212 -> 3 | H20: ='BILL NO4. (20 NHU)'!H212 -> 0 | I20: ='BILL NO4. (20 NHU)'!I212 -> 0
B21: ='BILL NO4. (20 NHU)'!B213 -> F3 | C21: ='BILL NO4. (20 NHU)'!C213 -> Fire Fighting Installation | D21: ='BILL NO4. (20 NHU)'!D213 -> outlet | E21: ='BILL NO4. (20 NHU)'!E213 -> Wet riser outlet with valve assembly | F21: ='BILL NO4. (20 NHU)'!F213 -> NO | G21: ='BILL NO4. (20 NHU)'!G213 -> 3 | H21: ='BILL NO4. (20 NHU)'!H213 -> 80 | I21: ='BILL NO4. (20 NHU)'!I213 -> 240 | J21: Pending | K21: Reason
B22: ='BILL NO4. (20 NHU)'!B214 -> F4 | C22: ='BILL NO4. (20 NHU)'!C214 -> Fire Fighting Installation | D22: ='BILL NO4. (20 NHU)'!D214 -> valve | E22: ='BILL NO4. (20 NHU)'!E214 -> Zonal control valve assembly | F22: ='BILL NO4. (20 NHU)'!F214 -> NO | G22: ='BILL NO4. (20 NHU)'!G214 -> 1 | H22: ='BILL NO4. (20 NHU)'!H214 -> 120 | I22: ='BILL NO4. (20 NHU)'!I214 -> 120 | J22: Pending | K22: Reason
B23: ='BILL NO4. (20 NHU)'!B215 -> F5 | C23: ='BILL NO4. (20 NHU)'!C215 -> Fire Fighting Installation | D23: ='BILL NO4. (20 NHU)'!D215 -> inlet | E23: ='BILL NO4. (20 NHU)'!E215 -> Breaching inlet | F23: ='BILL NO4. (20 NHU)'!F215 -> NO | G23: ='BILL NO4. (20 NHU)'!G215 -> 1 | H23: ='BILL NO4. (20 NHU)'!H215 -> 200 | I23: ='BILL NO4. (20 NHU)'!I215 -> 200 | J23: Cancelled | K23: Not possible
B24: ='BILL NO4. (20 NHU)'!B339 -> GN4 | C24: ='BILL NO4. (20 NHU)'!C339 -> Telephone System | D24: ='BILL NO4. (20 NHU)'!D339 -> Cable | E24: ='BILL NO4. (20 NHU)'!E339 -> Cable and conduits to telephone outlet points in concealed installation from telephone junction box to IP phone expansion module for reception | F24: ='BILL NO4. (20 NHU)'!F339 -> No | G24: ='BILL NO4. (20 NHU)'!G339 -> 120 | H24: ='BILL NO4. (20 NHU)'!H339 -> 2.45 | I24: ='BILL NO4. (20 NHU)'!I339 -> 294 | J24: Cancelled
B25: ='BILL NO4. (20 NHU)'!B340 -> GN5 | C25: ='BILL NO4. (20 NHU)'!C340 -> Telephone System | D25: ='BILL NO4. (20 NHU)'!D340 -> Outlet | E25: ='BILL NO4. (20 NHU)'!E340 -> Cat 6E telephone outlet | F25: ='BILL NO4. (20 NHU)'!F340 -> No | G25: ='BILL NO4. (20 NHU)'!G340 -> 120 | H25: ='BILL NO4. (20 NHU)'!H340 -> 2.45 | I25: ='BILL NO4. (20 NHU)'!I340 -> 294 | J25: Cancelled
B26: ='BILL NO4. (20 NHU)'!B341 -> GN6 | C26: ='BILL NO4. (20 NHU)'!C341 -> Telephone System | D26: ='BILL NO4. (20 NHU)'!D341 -> Junction box | E26: ='BILL NO4. (20 NHU)'!E341 -> Telephone junction box | F26: ='BILL NO4. (20 NHU)'!F341 -> No | G26: ='BILL NO4. (20 NHU)'!G341 -> 20 | H26: ='BILL NO4. (20 NHU)'!H341 -> 2.1 | I26: ='BILL NO4. (20 NHU)'!I341 -> 42 | J26: Cancelled
B27: ='BILL NO4. (20 NHU)'!B352 -> GN16 | C27: ='BILL NO4. (20 NHU)'!C352 -> Structured Cabling system | D27: ='BILL NO4. (20 NHU)'!D352 -> patch panel | E27: ='BILL NO4. (20 NHU)'!E352 -> 16 Port Cat 6A Patch panel | F27: ='BILL NO4. (20 NHU)'!F352 -> No | G27: ='BILL NO4. (20 NHU)'!G352 -> 20 | H27: ='BILL NO4. (20 NHU)'!H352 -> 8.4 | I27: ='BILL NO4. (20 NHU)'!I352 -> 168 | J27: Cancelled
B28: ='BILL NO4. (20 NHU)'!B353 -> GN17 | C28: ='BILL NO4. (20 NHU)'!C353 -> Structured Cabling system | D28: ='BILL NO4. (20 NHU)'!D353 -> Structured Cabling system | E28: ='BILL NO4. (20 NHU)'!E353 -> 500mm single mode fiber LC SC Patch cords | F28: ='BILL NO4. (20 NHU)'!F353 -> No | G28: ='BILL NO4. (20 NHU)'!G353 -> 20 | H28: ='BILL NO4. (20 NHU)'!H353 -> 9.45 | I28: ='BILL NO4. (20 NHU)'!I353 -> 189 | J28: Pending
B29: ='BILL NO4. (20 NHU)'!B355 -> GN18 | C29: ='BILL NO4. (20 NHU)'!C355 -> Structured Cabling system | D29: ='BILL NO4. (20 NHU)'!D355 -> Accessories | E29: ='BILL NO4. (20 NHU)'!E355 -> Accessories and stacking kits and cable management and cable organizer and cable channels and supports all types of cords and pig tail connectors including termination etc complete | F29: ='BILL NO4. (20 NHU)'!F355 -> Item | G29: ='BILL NO4. (20 NHU)'!G355 -> 1 | H29: ='BILL NO4. (20 NHU)'!H355 -> 1050 | I29: ='BILL NO4. (20 NHU)'!I355 -> 1050 | J29: Under Review
B30: ='BILL NO4. (20 NHU)'!B356 -> GN19 | C30: ='BILL NO4. (20 NHU)'!C356 -> CCTV System | D30: ='BILL NO4. (20 NHU)'!D356 -> PTZ Camera | E30: ='BILL NO4. (20 NHU)'!E356 -> PTZ Vandal proof with weather proof Bullet type Day and Night vision CCTV IP camera Outdoor as specified. | F30: ='BILL NO4. (20 NHU)'!F356 -> No | G30: ='BILL NO4. (20 NHU)'!G356 -> 40 | H30: ='BILL NO4. (20 NHU)'!H356 -> 26.25 | I30: ='BILL NO4. (20 NHU)'!I356 -> 1050 | J30: Under Review
B31: ='BILL NO4. (20 NHU)'!B357 -> GN20 | C31: ='BILL NO4. (20 NHU)'!C357 -> CCTV System | D31: ='BILL NO4. (20 NHU)'!D357 -> pulling box | E31: ='BILL NO4. (20 NHU)'!E357 -> Allow for cable pulling boxes | F31: ='BILL NO4. (20 NHU)'!F357 -> Item | G31: ='BILL NO4. (20 NHU)'!G357 -> 1 | H31: ='BILL NO4. (20 NHU)'!H357 -> 1575 | I31: ='BILL NO4. (20 NHU)'!I357 -> 1575 | J31: Under Review | K31: Basic Structure not available
B32: ='BILL NO4. (20 NHU)'!B259 -> E25 | C32: ='BILL NO4. (20 NHU)'!C259 -> MAIN DISTRIBUTION BOARD Electrical Engineering Installation | D32: ='BILL NO4. (20 NHU)'!D259 -> Main Distribution Board | E32: ='BILL NO4. (20 NHU)'!E259 -> Main Distribution panel board in weather proof Stainless steel enclosure IP 65 including 2 nos 600A and 4 nos 400A and 1NOS spare100 A and 1 NOS spare 200A Incoming MCCB Breaker and 4nos 200A and 2nos spare 100 A Outgoing MCCB Breakers and supports and Busbar and earthing and cable glands and Ammeters and Voltmeters and internal wiring interconnection 1PH 3PH KWH series meters and labels as per approved MHEW drawings | F32: ='BILL NO4. (20 NHU)'!F259 -> NO | G32: ='BILL NO4. (20 NHU)'!G259 -> 6 | H32: ='BILL NO4. (20 NHU)'!H259 -> 14 | I32: ='BILL NO4. (20 NHU)'!I259 -> 84 | J32: Under Review
I36: =SUM(I17:I35) -> 7196
B38: 20 NEW HOUSING UNITS - EXTERNAL WORKS
B40: ='BILL NO 4 (20 NHU EXTERNAL WORK'!B14 -> EW11 | C40: ='BILL NO 4 (20 NHU EXTERNAL WORK'!C14 -> External Works General Site Works | D40: ='BILL NO 4 (20 NHU EXTERNAL WORK'!D14 -> Design and Build Shaded Car Parking of 20 numbers with Solar Panel Canopy | E40: ='BILL NO 4 (20 NHU EXTERNAL WORK'!E14 -> Allow for the Contractor to design and build the Shaded Car Park for houses with Solar Panel Canopy as per Engineer Employer Instruction. | F40: ='BILL NO 4 (20 NHU EXTERNAL WORK'!F14 -> no | G40: ='BILL NO 4 (20 NHU EXTERNAL WORK'!G14 -> 105 | H40: ='BILL NO 4 (20 NHU EXTERNAL WORK'!H14 -> 20 | I40: ='BILL NO 4 (20 NHU EXTERNAL WORK'!I14 -> 2100 | J40: Under Review
B41: ='BILL NO 4 (20 NHU EXTERNAL WORK'!B6 -> EW3 | C41: ='BILL NO 4 (20 NHU EXTERNAL WORK'!C6 -> External Works General Site Works | D41: ='BILL NO 4 (20 NHU EXTERNAL WORK'!D6 -> Wicket Gate | E41: ='BILL NO 4 (20 NHU EXTERNAL WORK'!E6 -> Allow for the Contractor to supply fabricate and installation of single leaf Wicket Gate as per the Architectural Drawing and follow as per Engineer Employer Instructions including anti corrotion epoxy paint. | F41: ='BILL NO 4 (20 NHU EXTERNAL WORK'!F6 -> no | G41: ='BILL NO 4 (20 NHU EXTERNAL WORK'!G6 -> 105 | H41: ='BILL NO 4 (20 NHU EXTERNAL WORK'!H6 -> 20 | I41: ='BILL NO 4 (20 NHU EXTERNAL WORK'!I6 -> 2100 | J41: Pending
B42: ='BILL NO 4 (20 NHU EXTERNAL WORK'!B7 -> EW4 | C42: ='BILL NO 4 (20 NHU EXTERNAL WORK'!C7 -> External Works General Site Works | D42: ='BILL NO 4 (20 NHU EXTERNAL WORK'!D7 -> Car Entrance Gate | E42: ='BILL NO 4 (20 NHU EXTERNAL WORK'!E7 -> Allow for the Contractor to supply fabricate and installation of single leaf Car Entrance Gate as per the Architectural Drawing and follow as per Engineer Employer Instructions including anti corrotion epoxy paint | F42: ='BILL NO 4 (20 NHU EXTERNAL WORK'!F7 -> no | G42: ='BILL NO 4 (20 NHU EXTERNAL WORK'!G7 -> 141.75 | H42: ='BILL NO 4 (20 NHU EXTERNAL WORK'!H7 -> 20 | I42: ='BILL NO 4 (20 NHU EXTERNAL WORK'!I7 -> 2835 | J42: Pending
I44: =SUM(I40:I43) -> 7035
B46: BILL NO. 5 - (29 MAINTENANCE HOUSING UNITS)
B48: ='BILL NO 5. (MAINTENANCE HOUSING'!B27 -> C11 | C48: ='BILL NO 5. (MAINTENANCE HOUSING'!C27 -> Superstructure Works Metal Works | D48: ='BILL NO 5. (MAINTENANCE HOUSING'!D27 -> galvanized steel cat Ladder | E48: ='BILL NO 5. (MAINTENANCE HOUSING'!E27 -> Supply and install galvanized steel cat Ladder as specified and detailed on the drawingas per exixting desin hand rail in new houses drawings. | F48: ='BILL NO 5. (MAINTENANCE HOUSING'!F27 -> Item | G48: ='BILL NO 5. (MAINTENANCE HOUSING'!G27 -> 29 | H48: ='BILL NO 5. (MAINTENANCE HOUSING'!H27 -> 262.5 | I48: =G48*H48 -> 7612.5 | J48: Pending
B49: ='BILL NO 5. (MAINTENANCE HOUSING'!B108 -> E25 | C49: ='BILL NO 5. (MAINTENANCE HOUSING'!C108 -> Electrical Engineering Installation | D49: ='BILL NO 5. (MAINTENANCE HOUSING'!D108 -> Lighting Fixture | E49: ='BILL NO 5. (MAINTENANCE HOUSING'!E108 -> Supply install connect test and commission of the following lighting fixtures Emergency light | F49: ='BILL NO 5. (MAINTENANCE HOUSING'!F108 -> Item | G49: ='BILL NO 5. (MAINTENANCE HOUSING'!G108 -> 29 | H49: ='BILL NO 5. (MAINTENANCE HOUSING'!H108 -> 17.379 | I49: =G49*H49 -> 503.991 | J49: Under Review
I51: =SUM(I48:I50) -> 8116.491
B53: BILL NO. 6 (STORM WATER PROTECTION)
B54: ='BILL NO 6 (STORM WATER)'!B6 -> PSW9 | C54: ='BILL NO 6 (STORM WATER)'!C6 -> Earthwork | D54: ='BILL NO 6 (STORM WATER)'!D6 -> Earthwork for pipe Trenches | E54: ='BILL NO 6 (STORM WATER)'!E6 -> Trench excavation and backfilling Depth 0 to 2m | F54: ='BILL NO 6 (STORM WATER)'!F6 -> m3 | G54: ='BILL NO 6 (STORM WATER)'!G6 -> 9180 | H54: ='BILL NO 6 (STORM WATER)'!H6 -> 0.7 | I54: =G54*H54 -> 6426 | J54: Cancelled
B55: ='BILL NO 6 (STORM WATER)'!B7 -> PSW10 | C55: ='BILL NO 6 (STORM WATER)'!C7 -> Earthwork | D55: ='BILL NO 6 (STORM WATER)'!D7 -> Earthwork for pipe Trenches | E55: ='BILL NO 6 (STORM WATER)'!E7 -> Trench excavation and backfilling Depth 2m to 2m | F55: ='BILL NO 6 (STORM WATER)'!F7 -> m3 | G55: ='BILL NO 6 (STORM WATER)'!G7 -> 12615 | H55: ='BILL NO 6 (STORM WATER)'!H7 -> 1.575 | I55: =G55*H55 -> 19868.625 | J55: Cancelled
B56: ='BILL NO 6 (STORM WATER)'!B8 -> PSW11 | C56: ='BILL NO 6 (STORM WATER)'!C8 -> Earthwork | D56: ='BILL NO 6 (STORM WATER)'!D8 -> Earthwork for pipe Trenches | E56: ='BILL NO 6 (STORM WATER)'!E8 -> Trench excavation and backfilling Depth 3m to 4m | F56: ='BILL NO 6 (STORM WATER)'!F8 -> m3 | G56: ='BILL NO 6 (STORM WATER)'!G8 -> 3090 | H56: ='BILL NO 6 (STORM WATER)'!H8 -> 2.1 | I56: =G56*H56 -> 6489 | J56: Cancelled
B57: ='BILL NO 6 (STORM WATER)'!B9 -> PSW12 | C57: ='BILL NO 6 (STORM WATER)'!C9 -> Earthwork | D57: ='BILL NO 6 (STORM WATER)'!D9 -> Earthwork for pipe Trenches | E57: ='BILL NO 6 (STORM WATER)'!E9 -> Trench excavation and backfilling Depth more than 4m | F57: ='BILL NO 6 (STORM WATER)'!F9 -> m3 | G57: ='BILL NO 6 (STORM WATER)'!G9 -> 4080 | H57: ='BILL NO 6 (STORM WATER)'!H9 -> 4.2 | I57: =G57*H57 -> 17136 | J57: Cancelled
B58: ='BILL NO 6 (STORM WATER)'!B10 -> PSW13 | C58: ='BILL NO 6 (STORM WATER)'!C10 -> 3 Granular Subbase Aggregate Base Course and Stabilized Base Courses. | D58: ='BILL NO 6 (STORM WATER)'!D10 -> Redesign and Construction of Asphalt Road to be suitable for Erection of Culvert with all necessary drawings details… | E58: ='BILL NO 6 (STORM WATER)'!E10 -> Aggregate Base Course Class B | F58: ='BILL NO 6 (STORM WATER)'!F10 -> m3 | G58: ='BILL NO 6 (STORM WATER)'!G10 -> 1500 | H58: ='BILL NO 6 (STORM WATER)'!H10 -> 2.1 | I58: =G58*H58 -> 3150 | J58: Cancelled
B59: ='BILL NO 6 (STORM WATER)'!B11 -> PSW14 | C59: ='BILL NO 6 (STORM WATER)'!C11 -> 4 Bituminous Pavement | D59: ='BILL NO 6 (STORM WATER)'!D11 -> Redesign and Construction of Asphalt Road to be suitable for Erection of Culvert with all necessary drawings details… | E59: ='BILL NO 6 (STORM WATER)'!E11 -> Bituminous Prime Coat Application rate 1.5 KgSq.m | F59: ='BILL NO 6 (STORM WATER)'!F11 -> m3 | G59: ='BILL NO 6 (STORM WATER)'!G11 -> 4050 | H59: ='BILL NO 6 (STORM WATER)'!H11 -> 2.1 | I59: =G59*H59 -> 8505 | J59: Cancelled
